<mujoco model="linkerhand_l21_right_urdf">
    <compiler angle="radian" />
    <size njmax="500" nconmax="100" />
    <asset>
        <!-- 蓝白棋盘纹理 -->
        <texture name="grid_tex" type="2d" builtin="checker" rgb1="0.2 0.3 0.8" rgb2="1 1 1" width="512" height="512"/>
        
        <!-- 关联纹理的材质 -->
        <material name="grid_material" texture="grid_tex" texrepeat="10 10" specular="0.3" shininess="0.5"/>
        <mesh name="hand_base_link" file="hand_base_link.STL" />
        <mesh name="index_metacarpals" file="index_metacarpals.STL" />
        <mesh name="index_proximal" file="index_proximal.STL" />
        <mesh name="index_middle" file="index_middle.STL" />
        <mesh name="middle_metacarpals" file="middle_metacarpals.STL" />
        <mesh name="middle_proximal" file="middle_proximal.STL" />
        <mesh name="middle_middle" file="middle_middle.STL" />
        <mesh name="ring_metacarpals" file="ring_metacarpals.STL" />
        <mesh name="ring_proximal" file="ring_proximal.STL" />
        <mesh name="ring_middle" file="ring_middle.STL" />
        <mesh name="pinky_metacarpals" file="pinky_metacarpals.STL" />
        <mesh name="pinky_proximal" file="pinky_proximal.STL" />
        <mesh name="pinky_middle" file="pinky_middle.STL" />
        <mesh name="thumb_metacarpals_base1" file="thumb_metacarpals_base1.STL" />
        <mesh name="thumb_metacarpals_base2" file="thumb_metacarpals_base2.STL" />
        <mesh name="thumb_metacarpals" file="thumb_metacarpals.STL" />
        <mesh name="thumb_proximal" file="thumb_proximal.STL" />
        <mesh name="thumb_distal" file="thumb_distal.STL" />
    </asset>
    <visual>
        <quality shadowsize="4096"/>
        <map znear="0.05"/>
        <global offwidth="1280" offheight="720"/>
    </visual>
    <default>
        <joint limited="true" damping="0.1" armature="0.01"/>
        <motor ctrllimited="true"/>
        <geom condim="3" contype="1" conaffinity="1" solref="0.01 1" solimp="0.9 0.95 0.001" friction="1.0 0.005 0.0001"/>
        <equality solref="0.01 1"/>
    </default>
    <worldbody>
        <!-- 蓝白方格地面 -->
        <geom 
        name="floor" 
        type="plane" 
        pos="0 0 0" 
        size="5 5 0.1" 
        material="grid_material"
        conaffinity="1" 
        condim="3"
        />
        <light directional="true" diffuse=".4 .4 .4" specular=".1 .1 .1" pos="0 0 5" dir="0 0 -1"/>
        <geom type="mesh" rgba="0.792157 0.819608 0.933333 1" mesh="hand_base_link" />
        <body name="index_metacarpals" pos="0.0114834 0.0329079 0.133378" quat="0.999996 0.00283226 0 0">
            <inertial pos="-0.000174296 -0.00266453 -0.0152796" quat="0.69128 0.720917 -0.0335089 0.0358863" mass="0.000419912" diaginertia="1.23705e-08 7.47853e-09 5.56177e-09" />
            <joint name="index_mcp_roll" pos="0 0 0" axis="1 0 0" limited="true" range="-0.18 0.18" />
            <geom type="mesh" rgba="0.792157 0.819608 0.933333 1" mesh="index_metacarpals" />
            <body name="index_proximal" pos="-0.00314196 0.000199976 0.0180749" quat="0.999228 0 -0.0392807 0">
                <inertial pos="-0.0188457 -0.0328777 -0.0733084" quat="0.998937 0.0355402 0.000402544 0.0293596" mass="0.0837097" diaginertia="0.000204696 0.000170505 0.000108171" />
                <joint name="index_mcp_pitch" pos="0 0 0" axis="0 1 0" limited="true" range="0 1.57" />
                <geom type="mesh" rgba="0.792157 0.819608 0.933333 1" mesh="index_proximal" />
                <body name="index_middle" pos="-0.000158 0 0.044">
                    <inertial pos="-0.0186877 -0.0328777 -0.117308" quat="0.998937 0.0355402 0.000402544 0.0293596" mass="0.0837097" diaginertia="0.000204696 0.000170505 0.000108171" />
                    <joint name="index_pip" pos="0 0 0" axis="0 1 0" limited="true" range="0 1.57" />
                    <geom type="mesh" rgba="0.792157 0.819608 0.933333 1" mesh="index_middle" />
                </body>
            </body>
        </body>
        <body name="middle_metacarpals" pos="0.011484 0.0107658 0.140753" quat="0.999996 0.00283226 0 0">
            <inertial pos="0.00259568 -0.000967747 -0.0158496" quat="0.71097 0.701861 -0.0301001 0.0317211" mass="0.000490013" diaginertia="1.70907e-08 1.16066e-08 6.25172e-09" />
            <joint name="middle_mcp_roll" pos="0 0 0" axis="1 0 0" limited="true" range="-0.18 0.18" />
            <geom type="mesh" rgba="0.792157 0.819608 0.933333 1" mesh="middle_metacarpals" />
            <body name="middle_proximal" pos="-0.00314197 0.000423562 0.0180749" quat="0.999228 0 -0.0392807 0">
                <inertial pos="-0.019435 -0.011001 -0.080785" quat="0.998937 0.0355424 0.000402619 0.0293588" mass="0.08371" diaginertia="0.000204698 0.000170506 0.000108175" />
                <joint name="middle_mcp_pitch" pos="0 0 0" axis="0 1 0" limited="true" range="0 1.57" />
                <geom type="mesh" rgba="0.79216 0.81961 0.93333 1" mesh="middle_proximal" />
                <body name="middle_middle" pos="-0.000158 0 0.044">
                    <inertial pos="-0.0192768 -0.0110046 -0.124785" quat="0.998937 0.0355402 0.000402544 0.0293596" mass="0.0837097" diaginertia="0.000204696 0.000170505 0.000108171" />
                    <joint name="middle_pip" pos="0 0 0" axis="0 1 0" limited="true" range="0 1.57" />
                    <geom type="mesh" rgba="0.792157 0.819608 0.933333 1" mesh="middle_middle" />
                </body>
            </body>
        </body>
        <body name="ring_metacarpals" pos="0.0114828 -0.0107912 0.133131" quat="0.999996 0.00283224 0 0">
            <inertial pos="0.000183739 -0.00100588 -0.0157139" quat="0.711187 0.701554 -0.0310397 0.0327244" mass="0.000471408" diaginertia="1.64187e-08 1.10982e-08 6.03928e-09" />
            <joint name="ring_mcp_roll" pos="0 0 0" axis="1 0 0" limited="true" range="-0.18 0.18" />
            <geom type="mesh" rgba="0.792157 0.819608 0.933333 1" mesh="ring_metacarpals" />
            <body name="ring_proximal" pos="-0.00314018 0.000423561 0.0180749" quat="0.999228 0 -0.0392807 0">
                <inertial pos="-0.0188465 0.0105985 -0.0733084" quat="0.998937 0.0355402 0.000402544 0.0293596" mass="0.0837097" diaginertia="0.000204696 0.000170505 0.000108171" />
                <joint name="ring_mcp_pitch" pos="0 0 0" axis="0 1 0" limited="true" range="0 1.57" />
                <geom type="mesh" rgba="0.792157 0.819608 0.933333 1" mesh="ring_proximal" />
                <body name="ring_middle" pos="-0.000158 0 0.044">
                    <inertial pos="-0.0186885 0.0105952 -0.117308" quat="0.998937 0.0355402 0.000402544 0.0293596" mass="0.0837097" diaginertia="0.000204696 0.000170505 0.000108171" />
                    <joint name="ring_pip" pos="0 0 0" axis="0 1 0" limited="true" range="0 1.57" />
                    <geom type="mesh" rgba="0.792157 0.819608 0.933333 1" mesh="ring_middle" />
                </body>
            </body>
        </body>
        <body name="pinky_metacarpals" pos="0.011483 -0.0328064 0.118068" quat="0.999996 0.00283226 0 0">
            <inertial pos="0.00220822 0.000457542 -0.0154296" quat="0.74303 0.667539 -0.0329477 0.0348216" mass="0.00043624" diaginertia="1.28618e-08 7.84367e-09 5.73032e-09" />
            <joint name="pinky_mcp_roll" pos="0 0 0" axis="1 0 0" limited="true" range="-0.18 0.18" />
            <geom type="mesh" rgba="0.792157 0.819608 0.933333 1" mesh="pinky_metacarpals" />
            <body name="pinky_proximal" pos="-0.00313977 0.000423562 0.0180749" quat="0.999228 0 -0.0392807 0">
                <inertial pos="-0.0176743 0.0326987 -0.0584165" quat="0.998937 0.0355402 0.000402544 0.0293596" mass="0.0837097" diaginertia="0.000204696 0.000170505 0.000108171" />
                <joint name="pinky_mcp_pitch" pos="0 0 0" axis="0 1 0" limited="true" range="0 1.57" />
                <geom type="mesh" rgba="0.792157 0.819608 0.933333 1" mesh="pinky_proximal" />
                <body name="pinky_middle" pos="-0.000158 0 0.044">
                    <inertial pos="-0.0175163 0.0326954 -0.102416" quat="0.998937 0.0355402 0.000402544 0.0293596" mass="0.0837097" diaginertia="0.000204696 0.000170505 0.000108171" />
                    <joint name="pinky_pip" pos="0 0 0" axis="0 1 0" limited="true" range="0 1.57" />
                    <geom type="mesh" rgba="0.792157 0.819608 0.933333 1" mesh="pinky_middle" />
                </body>
            </body>
        </body>
        <body name="thumb_metacarpals_base1" pos="-0.0038161 0.002009 0.071277" quat="0.999996 0.00283225 0 0">
            <inertial pos="-0.00205 -0.0055 -0.0318467" quat="0.707107 0.707107 0 0" mass="0.000312218" diaginertia="1.10352e-08 1.09679e-08 1.0338e-09" />
            <joint name="thumb_cmc_roll" pos="0 0 0" axis="1 0 0" limited="true" range="-0.6 0.6" />
            <geom type="mesh" rgba="0.792157 0.819608 0.933333 1" mesh="thumb_metacarpals_base1" />
            <body name="thumb_metacarpals_base2" pos="0.03345 0.008383 0.0026" quat="0.999933 0 0 0.0115717">
                <inertial pos="-0.0345428 -0.00901369 0.00283839" quat="0.997999 0.040555 0.0390716 0.028743" mass="0.0837097" diaginertia="0.000204591 0.000170667 0.000108114" />
                <joint name="thumb_cmc_yaw" pos="0 0 0" axis="0 0 -1" limited="true" range="0 1.6" />
                <geom type="mesh" rgba="0.792157 0.819608 0.933333 1" mesh="thumb_metacarpals_base2" />
                <body name="thumb_metacarpals" pos="0.0090013 0.014318 -0.00098753" quat="0.715225 0 0 0.698894">
                    <inertial pos="0.0039473 0.00763192 -0.0146443" quat="0.000945878 0.678949 -0.014352 0.734044" mass="8.32469e-05" diaginertia="8.34313e-10 7.21802e-10 1.98715e-10" />
                    <joint name="thumb_cmc_pitch" pos="0 0 0" axis="0 -1 0" limited="true" range="0 1" />
                    <geom type="mesh" rgba="0.792157 0.819608 0.933333 1" mesh="thumb_metacarpals" />
                    <body name="thumb_proximal" pos="0.033763 0.0030005 -0.0066361" quat="0.999156 -0.000456254 0.0394256 0.0115627">
                        <inertial pos="0.0470198 -0.0002 -0.016368" quat="0.999962 0 -0.0086836 0" mass="0.000276349" diaginertia="3.59254e-09 1.86536e-09 1.86536e-09" />
                        <joint name="thumb_mcp" pos="0 0 0" axis="0 -1 0" limited="true" range="0 1.57" />
                        <geom type="mesh" rgba="0.792157 0.819608 0.933333 1" mesh="thumb_proximal" />
                        <body name="thumb_distal" pos="0.04616 0 -0.0035646" quat="0.999214 0 0.0396526 0">
                            <inertial pos="-0.104387 0.0413258 0.00122242" quat="0.663219 0.0521502 -0.00098323 0.746606" mass="0.0837097" diaginertia="0.000204851 0.000170263 0.000108257" />
                            <joint name="thumb_ip" pos="0 0 0" axis="0 -1 0" limited="true" range="0 1.57" />
                            <geom type="mesh" rgba="0.792157 0.819608 0.933333 1" mesh="thumb_distal" />
                        </body>
                    </body>
                </body>
            </body>
        </body>
    </worldbody>
    <actuator>
        <position name="index_pos0" joint="index_mcp_roll" kp="10" ctrlrange="-0.18 0.18"/>
        <position name="index_pos1" joint="index_mcp_pitch" kp="10" ctrlrange="0 1.57"/>
        <position name="index_pos2" joint="index_pip" kp="10" ctrlrange="0 1.57"/>
        
        <position name="middle_pos0" joint="middle_mcp_roll" kp="10" ctrlrange="-0.18 0.18"/>
        <position name="middle_pos1" joint="middle_mcp_pitch" kp="10" ctrlrange="0 1.57"/>
        <position name="middle_pos2" joint="middle_pip" kp="10" ctrlrange="0 1.57"/>

        
        <position name="ring_pos0" joint="ring_mcp_roll" kp="10" ctrlrange="-0.18 0.18"/>
        <position name="ring_pos1" joint="ring_mcp_pitch" kp="10" ctrlrange="0 1.57"/>
        <position name="ring_pos2" joint="ring_pip" kp="10" ctrlrange="0 1.57"/>
        
        <position name="little_pos0" joint="pinky_mcp_roll" kp="10" ctrlrange="0 0.18"/>
        <position name="little_pos1" joint="pinky_mcp_pitch" kp="10" ctrlrange="0 1.57"/>
        <position name="little_pos2" joint="pinky_pip" kp="10" ctrlrange="0 1.57"/>

        <position name="thumb_pos0" joint="thumb_cmc_roll" kp="10" ctrlrange="-0.6 0.6"/>
        <position name="thumb_pos1" joint="thumb_cmc_yaw" kp="10" ctrlrange="0 1.6"/>
        <position name="thumb_pos2" joint="thumb_cmc_pitch" kp="10" ctrlrange="0 1"/>
        <position name="thumb_pos3" joint="thumb_mcp" kp="10" ctrlrange="0 1.57"/>
        <position name="thumb_pos4" joint="thumb_ip" kp="10" ctrlrange="0 1.57"/>
    </actuator>
</mujoco>
