<mujoco model="linker_hand_l10_left">
    <compiler angle="radian" />
    <size njmax="500" nconmax="100" />
    <asset>
        <!-- 蓝白棋盘纹理 -->
        <texture name="grid_tex" type="2d" builtin="checker" rgb1="0.2 0.3 0.8" rgb2="1 1 1" width="512" height="512"/>
        
        <!-- 关联纹理的材质 -->
        <material name="grid_material" texture="grid_tex" texrepeat="10 10" specular="0.3" shininess="0.5"/>
        <mesh name="base_link" file="base_link.STL" />
        <mesh name="thumb_link0" file="thumb_link0.STL" />
        <mesh name="thumb_link1" file="thumb_link1.STL" />
        <mesh name="thumb_link2" file="thumb_link2.STL" />
        <mesh name="thumb_link3" file="thumb_link3.STL" />
        <mesh name="thumb_link4" file="thumb_link4.STL" />
        <mesh name="thumb_link5" file="thumb_link5.STL" />
        <mesh name="index_link0" file="index_link0.STL" />
        <mesh name="index_link1" file="index_link1.STL" />
        <mesh name="index_link2" file="index_link2.STL" />
        <mesh name="index_link3" file="index_link3.STL" />
        <mesh name="index_link4" file="index_link4.STL" />
        <mesh name="middle_link0" file="middle_link0.STL" />
        <mesh name="middle_link1" file="middle_link1.STL" />
        <mesh name="middle_link2" file="middle_link2.STL" />
        <mesh name="middle_link3" file="middle_link3.STL" />
        <mesh name="ring_link0" file="ring_link0.STL" />
        <mesh name="ring_link1" file="ring_link1.STL" />
        <mesh name="ring_link2" file="ring_link2.STL" />
        <mesh name="ring_link3" file="ring_link3.STL" />
        <mesh name="ring_link4" file="ring_link4.STL" />
        <mesh name="little_link0" file="little_link0.STL" />
        <mesh name="little_link1" file="little_link1.STL" />
        <mesh name="little_link2" file="little_link2.STL" />
        <mesh name="little_link3" file="little_link3.STL" />
        <mesh name="little_link4" file="little_link4.STL" />
    </asset>
    <visual>
        <quality shadowsize="4096"/>
        <map znear="0.05"/>
        <global offwidth="1280" offheight="720"/>
    </visual>

  <default>
    <joint limited="true" damping="0.1" armature="0.01"/>
    <motor ctrllimited="true"/>
    <geom condim="3" contype="1" conaffinity="1" solref="0.01 1" solimp="0.9 0.95 0.001" friction="1.0 0.005 0.0001"/>
    <equality solref="0.01 1"/>
  </default>
    <worldbody>
        <!-- 蓝白方格地面 -->
        <geom 
        name="floor" 
        type="plane" 
        pos="0 0 0" 
        size="5 5 0.1" 
        material="grid_material"
        conaffinity="1" 
        condim="3"
        />
        <light directional="true" diffuse=".4 .4 .4" specular=".1 .1 .1" pos="0 0 5" dir="0 0 -1"/>
        <geom type="mesh" rgba="1 1 1 1" mesh="base_link" />
        <body name="thumb_link0" pos="-0.017939 -0.018426 0.086237">
            <inertial pos="0.0231869 -9.48627e-06 -0.00324883" quat="0.702183 -0.0892113 -0.0895304 0.700688" mass="0.0115245" diaginertia="4.3707e-06 3.16784e-06 1.87527e-06" />
            <joint name="thumb_joint0" pos="0 0 0" axis="1 0 0" limited="true" range="-1.01 0.52" />
            <geom type="mesh" rgba="1 1 1 1" mesh="thumb_link0" />
            <body name="thumb_link1" pos="0.0303 0 0.016812">
                <inertial pos="0.00028238 -0.000440867 -0.0153488" quat="0.699016 0.6344 0.221684 0.24448" mass="0.0170446" diaginertia="3.40367e-06 2.61452e-06 1.93957e-06" />
                <joint name="thumb_joint1" pos="0 0 0" axis="0 0 1" limited="true" range="0 1.43" />
                <geom type="mesh" rgba="1 1 1 1" mesh="thumb_link1" />
                <body name="thumb_link2" pos="0.020969 -0.020033 -0.018293" quat="0.944089 0 0 0.32969">
                    <inertial pos="-0.00445352 -0.0191765 0.0112773" quat="0.839152 0.543897 0.000148238 0.000249164" mass="0.0154404" diaginertia="4.16317e-06 3.18425e-06 1.43135e-06" />
                    <joint name="thumb_joint2" pos="0 0 0" axis="1 0 0" limited="true" range="-0.44 0" />
                    <geom type="mesh" rgba="1 1 1 1" mesh="thumb_link2" />
                    <body name="thumb_link3" pos="0.00418 -0.042527 0.02726">
                        <inertial pos="-0.00818377 -0.0138382 0.00588046" quat="0.567554 0.421896 -0.422261 0.567082" mass="0.00549845" diaginertia="9.94148e-07 8.89652e-07 3.98192e-07" />
                        <joint name="thumb_joint3" pos="0 0 0" axis="1 0 0" limited="true" range="-1.45 0" />
                        <geom type="mesh" rgba="1 1 1 1" mesh="thumb_link3" />
                        <body name="thumb_link4" pos="-0.00173 -0.034152 0.013346">
                            <inertial pos="-0.00625482 -0.0105872 0.00370366" quat="0.483693 0.514433 -0.515025 0.485952" mass="0.00484896" diaginertia="3.57916e-07 3.20877e-07 1.7935e-07" />
                            <joint name="thumb_joint4" pos="0 0 0" axis="1 0 0" limited="true" range="-0.7 0" />
                            <geom type="mesh" rgba="1 1 1 1" mesh="thumb_link4" />
                            <geom pos="-0.0055 -0.028238 0.0018333" type="mesh" rgba="1 1 1 1" mesh="thumb_link5" />
                        </body>
                    </body>
                </body>
            </body>
        </body>
        <body name="index_link0" pos="0.011645 -0.02293 0.15849">
            <inertial pos="-0.0145152 1.54228e-05 0.00937118" quat="0.48049 0.517058 0.523404 0.477314" mass="0.00412866" diaginertia="3.83464e-07 3.29927e-07 2.43301e-07" />
            <joint name="index_joint0" pos="0 0 0" axis="1 0 0" limited="true" range="0 0.26" />
            <geom type="mesh" rgba="1 1 1 1" mesh="index_link0" />
            <body name="index_link1" pos="-0.012765 -0.0085 0.017575">
                <inertial pos="-0.00432244 0.00844417 0.0189705" quat="0.987574 0.00135795 -0.156092 0.0181975" mass="0.00319121" diaginertia="2.91659e-07 2.67771e-07 1.37647e-07" />
                <joint name="index_joint1" pos="0 0 0" axis="0 1 0" limited="true" range="0 1.41" />
                <geom type="mesh" rgba="1 1 1 1" mesh="index_link1" />
                <body name="index_link2" pos="-0.0051959 0.0031156 0.033276">
                    <inertial pos="-0.00422895 0.00578281 0.0108417" quat="0.972764 0.0203089 -0.230849 -0.00507891" mass="0.00326734" diaginertia="2.97604e-07 2.61394e-07 1.21583e-07" />
                    <joint name="index_joint2" pos="0 0 0" axis="0 1 0" limited="true" range="0 1.62" />
                    <geom type="mesh" rgba="1 1 1 1" mesh="index_link2" />
                    <body name="index_link3" pos="-0.0097853 5.4404e-05 0.024348">
                        <inertial pos="-0.00330443 0.00532954 0.0112038" quat="0.941985 0.00477793 -0.334601 0.0261255" mass="0.0038651" diaginertia="2.21793e-07 2.06719e-07 9.47172e-08" />
                        <joint name="index_joint3" pos="0 0 0" axis="0 1 0" limited="true" range="0 0.96" />
                        <geom type="mesh" rgba="1 1 1 1" mesh="index_link3" />
                        <geom pos="-0.014675 0.00425 0.022509" type="mesh" rgba="1 1 1 1" mesh="index_link4" />
                    </body>
                </body>
            </body>
        </body>
        <body name="middle_link0" pos="-0.0031059 -0.01243 0.18107">
            <inertial pos="-0.00432244 0.00844417 0.0189705" quat="0.987574 0.00135795 -0.156092 0.0181975" mass="0.00319121" diaginertia="2.91659e-07 2.67771e-07 1.37647e-07" />
            <joint name="middle_joint0" pos="0 0 0" axis="0 1 0" limited="true" range="0 1.41" />
            <geom type="mesh" rgba="1 1 1 1" mesh="middle_link0" />
            <body name="middle_link1" pos="-0.0051959 0.0031156 0.033276">
                <inertial pos="-0.00422895 0.00578281 0.0108417" quat="0.972764 0.0203089 -0.230849 -0.0050789" mass="0.00326734" diaginertia="2.97604e-07 2.61394e-07 1.21583e-07" />
                <joint name="middle_joint1" pos="0 0 0" axis="0 1 0" limited="true" range="0 1.62" />
                <geom type="mesh" rgba="1 1 1 1" mesh="middle_link1" />
                <body name="middle_link2" pos="-0.0097853 -0.0001456 0.024348">
                    <inertial pos="-0.00330443 0.00552954 0.0112038" quat="0.941985 0.00477788 -0.334601 0.0261251" mass="0.0038651" diaginertia="2.21793e-07 2.06719e-07 9.47172e-08" />
                    <joint name="middle_joint2" pos="0 0 0" axis="0 1 0" limited="true" range="0 0.96" />
                    <geom type="mesh" rgba="1 1 1 1" mesh="middle_link2" />
                    <geom pos="-0.014675 0.00445 0.022509" type="mesh" rgba="1 1 1 1" mesh="middle_link3" />
                </body>
            </body>
        </body>
        <body name="ring_link0" pos="0.011645 0.01507 0.15849">
            <inertial pos="-0.0145152 1.54245e-05 0.00937119" quat="0.48049 0.517058 0.523404 0.477313" mass="0.00412867" diaginertia="3.83464e-07 3.29927e-07 2.43301e-07" />
            <joint name="ring_joint0" pos="0 0 0" axis="1 0 0" limited="true" range="-0.26 0" />
            <geom type="mesh" rgba="1 1 1 1" mesh="ring_link0" />
            <body name="ring_link1" pos="-0.012765 -0.0085 0.017575">
                <inertial pos="-0.00432244 0.00844417 0.0189705" quat="0.987574 0.00135795 -0.156092 0.0181975" mass="0.00319121" diaginertia="2.91659e-07 2.67771e-07 1.37647e-07" />
                <joint name="ring_joint1" pos="0 0 0" axis="0 1 0" limited="true" range="0 1.41" />
                <geom type="mesh" rgba="1 1 1 1" mesh="ring_link1" />
                <body name="ring_link2" pos="-0.0051959 0.0031156 0.033276">
                    <inertial pos="-0.00422895 0.00578281 0.0108417" quat="0.972764 0.0203089 -0.230849 -0.0050789" mass="0.00326734" diaginertia="2.97604e-07 2.61394e-07 1.21583e-07" />
                    <joint name="ring_joint2" pos="0 0 0" axis="0 1 0" limited="true" range="0 1.62" />
                    <geom type="mesh" rgba="1 1 1 1" mesh="ring_link2" />
                    <body name="ring_link3" pos="-0.0097853 -0.0001456 0.024348">
                        <inertial pos="-0.00330443 0.00552954 0.0112038" quat="0.941985 0.00477791 -0.334601 0.0261255" mass="0.0038651" diaginertia="2.21793e-07 2.06719e-07 9.47172e-08" />
                        <joint name="ring_joint3" pos="0 0 0" axis="0 1 0" limited="true" range="0 0.96" />
                        <geom type="mesh" rgba="1 1 1 1" mesh="ring_link3" />
                        <geom pos="-0.014675 0.00445 0.022509" type="mesh" rgba="1 1 1 1" mesh="ring_link4" />
                    </body>
                </body>
            </body>
        </body>
        <body name="little_link0" pos="0.013645 0.03407 0.15349">
            <inertial pos="-0.0145152 1.54245e-05 0.00937119" quat="0.48049 0.517058 0.523404 0.477313" mass="0.00412867" diaginertia="3.83464e-07 3.29927e-07 2.43301e-07" />
            <joint name="little_joint0" pos="0 0 0" axis="1 0 0" limited="true" range="-0.26 0" />
            <geom type="mesh" rgba="1 1 1 1" mesh="little_link0" />
            <body name="little_link1" pos="-0.012765 -0.0085 0.017575">
                <inertial pos="-0.00432244 0.00844417 0.0189705" quat="0.987574 0.00135795 -0.156092 0.0181975" mass="0.00319121" diaginertia="2.91659e-07 2.67771e-07 1.37647e-07" />
                <joint name="little_joint1" pos="0 0 0" axis="0 1 0" limited="true" range="0 1.41" />
                <geom type="mesh" rgba="1 1 1 1" mesh="little_link1" />
                <body name="little_link2" pos="-0.0051959 0.0031156 0.033276">
                    <inertial pos="-0.00422895 0.00578281 0.0108417" quat="0.972764 0.0203089 -0.230849 -0.0050789" mass="0.00326734" diaginertia="2.97604e-07 2.61394e-07 1.21583e-07" />
                    <joint name="little_joint2" pos="0 0 0" axis="0 1 0" limited="true" range="0 1.62" />
                    <geom type="mesh" rgba="1 1 1 1" mesh="little_link2" />
                    <body name="little_link3" pos="-0.0097853 -0.0001456 0.024348">
                        <inertial pos="-0.00330443 0.00552954 0.0112038" quat="0.941985 0.00477783 -0.334601 0.0261254" mass="0.0038651" diaginertia="2.21793e-07 2.06719e-07 9.47172e-08" />
                        <joint name="little_joint3" pos="0 0 0" axis="0 1 0" limited="true" range="0 0.96" />
                        <geom type="mesh" rgba="1 1 1 1" mesh="little_link3" />
                        <geom pos="-0.014675 0.00445 0.022509" type="mesh" rgba="1 1 1 1" mesh="little_link4" />
                    </body>
                </body>
            </body>
        </body>
    </worldbody>
    <actuator>
        <position name="thumb_pos0" joint="thumb_joint0" kp="10" ctrlrange="-0.1396 0.349"/>
        <position name="thumb_pos1" joint="thumb_joint1" kp="10" ctrlrange="0 1.57"/>
        <position name="thumb_pos2" joint="thumb_joint2" kp="10" ctrlrange="-1.57 0"/>
        <position name="thumb_pos3" joint="thumb_joint3" kp="10" ctrlrange="-1.57 0"/>
        <position name="thumb_pos4" joint="thumb_joint4" kp="10" ctrlrange="-1.57 0"/>
        
        <position name="index_pos0" joint="index_joint0" kp="10" ctrlrange="-0.26 0.26"/>
        <position name="index_pos1" joint="index_joint1" kp="10" ctrlrange="0 1.396"/>
        <position name="index_pos2" joint="index_joint2" kp="10" ctrlrange="0 1.57"/>
        <position name="index_pos3" joint="index_joint3" kp="10" ctrlrange="0 1.57"/>
        
        <position name="middle_pos0" joint="middle_joint0" kp="10" ctrlrange="0 1.57"/>
        <position name="middle_pos1" joint="middle_joint1" kp="10" ctrlrange="0 1.57"/>
        <position name="middle_pos2" joint="middle_joint2" kp="10" ctrlrange="0 1.57"/>

        
        <position name="ring_pos0" joint="ring_joint0" kp="10" ctrlrange="-0.26 0.26"/>
        <position name="ring_pos1" joint="ring_joint1" kp="10" ctrlrange="0 1.57"/>
        <position name="ring_pos2" joint="ring_joint2" kp="10" ctrlrange="0 1.57"/>
        <position name="ring_pos3" joint="ring_joint3" kp="10" ctrlrange="0 1.57"/>
        
        <position name="little_pos0" joint="little_joint0" kp="10" ctrlrange="-0.26 0.26"/>
        <position name="little_pos1" joint="little_joint1" kp="10" ctrlrange="0 1.57"/>
        <position name="little_pos2" joint="little_joint2" kp="10" ctrlrange="0 1.57"/>
        <position name="little_pos3" joint="little_joint3" kp="10" ctrlrange="0 1.57"/>
    </actuator>
</mujoco>
