<?xml version="1.0" encoding="utf-8"?>
<!-- This URDF was automatically created by SolidWorks to URDF Exporter! Originally created by Stephen Brawner (brawner@gmail.com) 
     Commit Version: 1.6.0-1-g15f4949  Build Version: 1.6.7594.29634
     For more information, please see http://wiki.ros.org/sw_urdf_exporter -->
<robot
  name="linkerhand_t24_1_right">
  <link
    name="base_link">
    <inertial>
      <origin
        xyz="0.00258739599199595 0.00890116360143403 0.139419533771663"
        rpy="0 0 0" />
      <mass
        value="0.269152839443886" />
      <inertia
        ixx="0.00177830804966392"
        ixy="-5.93935627663372E-05"
        ixz="2.69666193778981E-05"
        iyy="0.00147653758319417"
        iyz="0.000148619225191075"
        izz="0.000428398038832443" />
    </inertial>
    <visual>
      <origin
        xyz="0 0 0"
        rpy="0 0 0" />
      <geometry>
        <mesh
          filename="meshes/base_link.STL" />
      </geometry>
      <material
        name="">
        <color
          rgba="1 1 1 1" />
      </material>
    </visual>
    <collision>
      <origin
        xyz="0 0 0"
        rpy="0 0 0" />
      <geometry>
        <mesh
          filename="meshes/base_link.STL" />
      </geometry>
    </collision>
  </link>
  <link
    name="trumb_link0">
    <inertial>
      <origin
        xyz="-0.00191014368243104 0.00275969733370915 0.000842631887315579"
        rpy="0 0 0" />
      <mass
        value="0.00466562338059168" />
      <inertia
        ixx="2.18249754664417E-07"
        ixy="5.39712506031415E-09"
        ixz="-2.50095737897963E-08"
        iyy="1.88077142287716E-07"
        iyz="9.69090597953119E-09"
        izz="1.37244707692484E-07" />
    </inertial>
    <visual>
      <origin
        xyz="0 0 0"
        rpy="0 0 0" />
      <geometry>
        <mesh
          filename="meshes/trumb_link0.STL" />
      </geometry>
      <material
        name="">
        <color
          rgba="1 1 1 1" />
      </material>
    </visual>
    <collision>
      <origin
        xyz="0 0 0"
        rpy="0 0 0" />
      <geometry>
        <mesh
          filename="meshes/trumb_link0.STL" />
      </geometry>
    </collision>
  </link>
  <joint
    name="trumb_joint0"
    type="revolute">
    <origin
      xyz="-0.0064336 -0.0026725 0.068052"
      rpy="0.0026857 0 0" />
    <parent
      link="base_link" />
    <child
      link="trumb_link0" />
    <axis
      xyz="1 0 0" />
    <limit
      lower="-0.26"
      upper="0.61"
      effort="100"
      velocity="1" />
  </joint>
  <link
    name="trumb_link1">
    <inertial>
      <origin
        xyz="0.0107972965440593 -0.00780014885359367 -0.0106883405152574"
        rpy="0 0 0" />
      <mass
        value="0.0132849431009556" />
      <inertia
        ixx="5.73555307735334E-07"
        ixy="1.52007301908348E-08"
        ixz="-2.05107194782105E-07"
        iyy="1.24055475959824E-06"
        iyz="3.08915200839824E-08"
        izz="1.12041715669972E-06" />
    </inertial>
    <visual>
      <origin
        xyz="0 0 0"
        rpy="0 0 0" />
      <geometry>
        <mesh
          filename="meshes/trumb_link1.STL" />
      </geometry>
      <material
        name="">
        <color
          rgba="1 1 1 1" />
      </material>
    </visual>
    <collision>
      <origin
        xyz="0 0 0"
        rpy="0 0 0" />
      <geometry>
        <mesh
          filename="meshes/trumb_link1.STL" />
      </geometry>
    </collision>
  </link>
  <joint
    name="trumb_joint1"
    type="revolute">
    <origin
      xyz="0.006 0.00325 0.0036559"
      rpy="0 0 1.3075" />
    <parent
      link="trumb_link0" />
    <child
      link="trumb_link1" />
    <axis
      xyz="0 0 1" />
    <limit
      lower="-1.43"
      upper="0"
      effort="100"
      velocity="1" />
  </joint>
  <link
    name="trumb_link2">
    <inertial>
      <origin
        xyz="-0.0138667483899618 0.00254958129898298 0.0713379364969491"
        rpy="0 0 0" />
      <mass
        value="0.269152839443886" />
      <inertia
        ixx="0.00146793673117189"
        ixy="-2.43557236314711E-05"
        ixz="0.000147718033673625"
        iyy="0.00178773349062417"
        iyz="1.17600361514915E-05"
        izz="0.000427573449894473" />
    </inertial>
    <visual>
      <origin
        xyz="0 0 0"
        rpy="0 0 0" />
      <geometry>
        <mesh
          filename="meshes/trumb_link2.STL" />
      </geometry>
      <material
        name="">
        <color
          rgba="1 1 1 1" />
      </material>
    </visual>
    <collision>
      <origin
        xyz="0 0 0"
        rpy="0 0 0" />
      <geometry>
        <mesh
          filename="meshes/trumb_link2.STL" />
      </geometry>
    </collision>
  </link>
  <joint
    name="trumb_joint2"
    type="revolute">
    <origin
      xyz="0.022883 -0.00325 -0.0036559"
      rpy="0 -0.00011487 0" />
    <parent
      link="trumb_link1" />
    <child
      link="trumb_link2" />
    <axis
      xyz="0 -1 0" />
    <limit
      lower="0"
      upper="0.89"
      effort="100"
      velocity="1" />
  </joint>
  <link
    name="trumb_link3">
    <inertial>
      <origin
        xyz="-0.0531779257749569 -0.0674226477836501 -0.00327423905078019"
        rpy="0 0 0" />
      <mass
        value="0.269152839443886" />
      <inertia
        ixx="0.0014706711144407"
        ixy="-0.000137788652963271"
        ixz="-2.38819654247802E-05"
        iyy="0.000424785694139104"
        iyz="-8.43109267516766E-06"
        izz="0.00178778686311073" />
    </inertial>
    <visual>
      <origin
        xyz="0 0 0"
        rpy="0 0 0" />
      <geometry>
        <mesh
          filename="meshes/trumb_link3.STL" />
      </geometry>
      <material
        name="">
        <color
          rgba="1 1 1 1" />
      </material>
    </visual>
    <collision>
      <origin
        xyz="0 0 0"
        rpy="0 0 0" />
      <geometry>
        <mesh
          filename="meshes/trumb_link3.STL" />
      </geometry>
    </collision>
  </link>
  <joint
    name="trumb_joint3"
    type="revolute">
    <origin
      xyz="0.039954 0.006 0.0044366"
      rpy="-1.5682 -0.0095791 0" />
    <parent
      link="trumb_link2" />
    <child
      link="trumb_link3" />
    <axis
      xyz="0 0.0026132 1" />
    <limit
      lower="-1.57"
      upper="0"
      effort="100"
      velocity="1" />
  </joint>
  <link
    name="trumb_link4">
    <inertial>
      <origin
        xyz="-0.0959366778925846 -0.00345041867474483 0.0721354631429822"
        rpy="0 0 0" />
      <mass
        value="0.269152839443886" />
      <inertia
        ixx="0.00147586931101162"
        ixy="-2.39914328826128E-05"
        ixz="0.00011621070027556"
        iyy="0.00178773349062445"
        iyz="1.24864274973324E-05"
        izz="0.000419640870054461" />
    </inertial>
    <visual>
      <origin
        xyz="0 0 0"
        rpy="0 0 0" />
      <geometry>
        <mesh
          filename="meshes/trumb_link4.STL" />
      </geometry>
      <material
        name="">
        <color
          rgba="1 1 1 1" />
      </material>
    </visual>
    <collision>
      <origin
        xyz="0 0 0"
        rpy="0 0 0" />
      <geometry>
        <mesh
          filename="meshes/trumb_link4.STL" />
      </geometry>
    </collision>
  </link>
  <joint
    name="trumb_joint4"
    type="revolute">
    <origin
      xyz="0.044215 0.002743 0"
      rpy="1.5682 -5.3483E-05 -0.020468" />
    <parent
      link="trumb_link3" />
    <child
      link="trumb_link4" />
    <axis
      xyz="0 1 0" />
    <limit
      lower="-1.57"
      upper="0"
      effort="100"
      velocity="1" />
  </joint>
  <link
    name="trumb_link5">
    <inertial>
      <origin
        xyz="-0.000345767318641471 2.09452099747542E-07 -7.36364440549614E-05"
        rpy="0 0 0" />
      <mass
        value="1.25E-07" />
      <inertia
        ixx="5.20833333333333E-15"
        ixy="-9.17050802319426E-30"
        ixz="2.03216424011964E-29"
        iyy="5.20833333333329E-15"
        iyz="-2.42821247388343E-30"
        izz="5.20833333333336E-15" />
    </inertial>
    <visual>
      <origin
        xyz="0 0 0"
        rpy="0 0 0" />
      <geometry>
        <mesh
          filename="meshes/trumb_link5.STL" />
      </geometry>
      <material
        name="">
        <color
          rgba="1 1 1 1" />
      </material>
    </visual>
    <collision>
      <origin
        xyz="0 0 0"
        rpy="0 0 0" />
      <geometry>
        <mesh
          filename="meshes/trumb_link5.STL" />
      </geometry>
    </collision>
  </link>
  <joint
    name="trumb_joint5"
    type="fixed">
    <origin
      xyz="0.044396 -0.0059997 -0.010129"
      rpy="0 0 0" />
    <parent
      link="trumb_link4" />
    <child
      link="trumb_link5" />
    <axis
      xyz="0 0 0" />
  </joint>
  <link
    name="index_link0">
    <inertial>
      <origin
        xyz="-0.0116738400150615 -0.0249846423618668 0.00541127703895714"
        rpy="0 0 0" />
      <mass
        value="0.269152839443886" />
      <inertia
        ixx="0.0017783079720147"
        ixy="-5.93211342635092E-05"
        ixz="2.71279767148864E-05"
        iyy="0.00147732829997939"
        iyz="0.000145802064392195"
        izz="0.000427607399696438" />
    </inertial>
    <visual>
      <origin
        xyz="0 0 0"
        rpy="0 0 0" />
      <geometry>
        <mesh
          filename="meshes/index_link0.STL" />
      </geometry>
      <material
        name="">
        <color
          rgba="1 1 1 1" />
      </material>
    </visual>
    <collision>
      <origin
        xyz="0 0 0"
        rpy="0 0 0" />
      <geometry>
        <mesh
          filename="meshes/index_link0.STL" />
      </geometry>
    </collision>
  </link>
  <joint
    name="index_joint0"
    type="revolute">
    <origin
      xyz="0.014261 0.0339 0.13408"
      rpy="0.0026857 0 0" />
    <parent
      link="base_link" />
    <child
      link="index_link0" />
    <axis
      xyz="1 0 0" />
    <limit
      lower="-0.18"
      upper="0"
      effort="100"
      velocity="1" />
  </joint>
  <link
    name="index_link1">
    <inertial>
      <origin
        xyz="-0.00540393374272892 -0.0274846423619768 -0.0117160692076493"
        rpy="0 0 0" />
      <mass
        value="0.269152839443886" />
      <inertia
        ixx="0.00177766272537291"
        ixy="-6.07179790083106E-05"
        ixz="4.00879755757671E-05"
        iyy="0.00147732829997939"
        iyz="0.000145225913584595"
        izz="0.000428252646338224" />
    </inertial>
    <visual>
      <origin
        xyz="0 0 0"
        rpy="0 0 0" />
      <geometry>
        <mesh
          filename="meshes/index_link1.STL" />
      </geometry>
      <material
        name="">
        <color
          rgba="1 1 1 1" />
      </material>
    </visual>
    <collision>
      <origin
        xyz="0 0 0"
        rpy="0 0 0" />
      <geometry>
        <mesh
          filename="meshes/index_link1.STL" />
      </geometry>
    </collision>
  </link>
  <joint
    name="index_joint1"
    type="revolute">
    <origin
      xyz="-0.0061577 0.0025 0.017075"
      rpy="0 0.0095993 0" />
    <parent
      link="index_link0" />
    <child
      link="index_link1" />
    <axis
      xyz="0 1 0" />
    <limit
      lower="0"
      upper="1.57"
      effort="100"
      velocity="1" />
  </joint>
  <link
    name="index_link2">
    <inertial>
      <origin
        xyz="-0.00484277615558324 -0.0309846423660203 -0.0537126175656924"
        rpy="0 0 0" />
      <mass
        value="0.269152839443886" />
      <inertia
        ixx="0.00177766272537291"
        ixy="-6.07179790083098E-05"
        ixz="4.00879755757657E-05"
        iyy="0.0014773282999794"
        iyz="0.000145225913584584"
        izz="0.000428252646338221" />
    </inertial>
    <visual>
      <origin
        xyz="0 0 0"
        rpy="0 0 0" />
      <geometry>
        <mesh
          filename="meshes/index_link2.STL" />
      </geometry>
      <material
        name="">
        <color
          rgba="1 1 1 1" />
      </material>
    </visual>
    <collision>
      <origin
        xyz="0 0 0"
        rpy="0 0 0" />
      <geometry>
        <mesh
          filename="meshes/index_link2.STL" />
      </geometry>
    </collision>
  </link>
  <joint
    name="index_joint2"
    type="revolute">
    <origin
      xyz="-0.00056116 0.0035 0.041997"
      rpy="0 0 0" />
    <parent
      link="index_link1" />
    <child
      link="index_link2" />
    <axis
      xyz="0 1 0" />
    <limit
      lower="0"
      upper="1.57"
      effort="100"
      velocity="1" />
  </joint>
  <link
    name="index_link3">
    <inertial>
      <origin
        xyz="0.000731836437005504 -0.0309846423707089 -0.0979473866863188"
        rpy="0 0 0" />
      <mass
        value="0.269152839443886" />
      <inertia
        ixx="0.00177421861342153"
        ixy="-6.48905123172789E-05"
        ixz="7.90107793802022E-05"
        iyy="0.00147732829997989"
        iyz="0.000143410112484766"
        izz="0.000431696758289107" />
    </inertial>
    <visual>
      <origin
        xyz="0 0 0"
        rpy="0 0 0" />
      <geometry>
        <mesh
          filename="meshes/index_link3.STL" />
      </geometry>
      <material
        name="">
        <color
          rgba="1 1 1 1" />
      </material>
    </visual>
    <collision>
      <origin
        xyz="0 0 0"
        rpy="0 0 0" />
      <geometry>
        <mesh
          filename="meshes/index_link3.STL" />
      </geometry>
    </collision>
  </link>
  <joint
    name="index_joint3"
    type="revolute">
    <origin
      xyz="-0.002743 0 0.044215"
      rpy="0 0.02891 0" />
    <parent
      link="index_link2" />
    <child
      link="index_link3" />
    <axis
      xyz="0 1 0" />
    <limit
      lower="0"
      upper="1.57"
      effort="100"
      velocity="1" />
  </joint>
  <link
    name="index_link4">
    <inertial>
      <origin
        xyz="-0.000349434973883823 -4.11141635459078E-07 5.35951185556272E-05"
        rpy="0 0 0" />
      <mass
        value="1.24999999999997E-07" />
      <inertia
        ixx="5.20833333333303E-15"
        ixy="1.36384265347506E-29"
        ixz="-3.14558285956878E-29"
        iyy="5.20833333333322E-15"
        iyz="-3.40964343130674E-29"
        izz="5.20833333333309E-15" />
    </inertial>
    <visual>
      <origin
        xyz="0 0 0"
        rpy="0 0 0" />
      <geometry>
        <mesh
          filename="meshes/index_link4.STL" />
      </geometry>
      <material
        name="">
        <color
          rgba="1 1 1 1" />
      </material>
    </visual>
    <collision>
      <origin
        xyz="0 0 0"
        rpy="0 0 0" />
      <geometry>
        <mesh
          filename="meshes/index_link4.STL" />
      </geometry>
    </collision>
  </link>
  <joint
    name="index_joint4"
    type="fixed">
    <origin
      xyz="-0.012677 -0.0059997 0.043737"
      rpy="0 0 0" />
    <parent
      link="index_link3" />
    <child
      link="index_link4" />
    <axis
      xyz="0 0 0" />
  </joint>
  <link
    name="middle_link0">
    <inertial>
      <origin
        xyz="-0.0109304819869269 -0.00221632614720707 -0.00220331857411777"
        rpy="0 0 0" />
      <mass
        value="0.269152839443886" />
      <inertia
        ixx="0.0017783079720147"
        ixy="-5.93211342635094E-05"
        ixz="2.71279767148867E-05"
        iyy="0.00147732829997939"
        iyz="0.000145802064392195"
        izz="0.000427607399696438" />
    </inertial>
    <visual>
      <origin
        xyz="0 0 0"
        rpy="0 0 0" />
      <geometry>
        <mesh
          filename="meshes/middle_link0.STL" />
      </geometry>
      <material
        name="">
        <color
          rgba="1 1 1 1" />
      </material>
    </visual>
    <collision>
      <origin
        xyz="0 0 0"
        rpy="0 0 0" />
      <geometry>
        <mesh
          filename="meshes/middle_link0.STL" />
      </geometry>
    </collision>
  </link>
  <joint
    name="middle_joint0"
    type="revolute">
    <origin
      xyz="0.013518 0.011112 0.14163"
      rpy="0.0026857 0 0" />
    <parent
      link="base_link" />
    <child
      link="middle_link0" />
    <axis
      xyz="1 0 0" />
    <limit
      lower="0"
      upper="0"
      effort="100"
      velocity="1" />
  </joint>
  <link
    name="middle_link1">
    <inertial>
      <origin
        xyz="-0.00533194001687153 -0.00488464236319619 -0.0192157236623227"
        rpy="0 0 0" />
      <mass
        value="0.269152839443886" />
      <inertia
        ixx="0.00177766272537291"
        ixy="-6.07179790074989E-05"
        ixz="4.00879755769901E-05"
        iyy="0.00147732829998527"
        iyz="0.00014522591356337"
        izz="0.000428252646332347" />
    </inertial>
    <visual>
      <origin
        xyz="0 0 0"
        rpy="0 0 0" />
      <geometry>
        <mesh
          filename="meshes/middle_link1.STL" />
      </geometry>
      <material
        name="">
        <color
          rgba="1 1 1 1" />
      </material>
    </visual>
    <collision>
      <origin
        xyz="0 0 0"
        rpy="0 0 0" />
      <geometry>
        <mesh
          filename="meshes/middle_link1.STL" />
      </geometry>
    </collision>
  </link>
  <joint
    name="middle_joint1"
    type="revolute">
    <origin
      xyz="-0.0054143 0.0026683 0.01696"
      rpy="0 0.0095993 0" />
    <parent
      link="middle_link0" />
    <child
      link="middle_link1" />
    <axis
      xyz="0 1 0" />
    <limit
      lower="0"
      upper="1.57"
      effort="100"
      velocity="1" />
  </joint>
  <link
    name="middle_link2">
    <inertial>
      <origin
        xyz="-0.00477201854191357 -0.00838464237202477 -0.0612121756676154"
        rpy="0 0 0" />
      <mass
        value="0.269152839443886" />
      <inertia
        ixx="0.00177766434388306"
        ixy="-6.07150463278508E-05"
        ixz="4.00607257482394E-05"
        iyy="0.00147732829998059"
        iyz="0.000145227139685569"
        izz="0.000428251027826884" />
    </inertial>
    <visual>
      <origin
        xyz="0 0 0"
        rpy="0 0 0" />
      <geometry>
        <mesh
          filename="meshes/middle_link2.STL" />
      </geometry>
      <material
        name="">
        <color
          rgba="1 1 1 1" />
      </material>
    </visual>
    <collision>
      <origin
        xyz="0 0 0"
        rpy="0 0 0" />
      <geometry>
        <mesh
          filename="meshes/middle_link2.STL" />
      </geometry>
    </collision>
  </link>
  <joint
    name="middle_joint2"
    type="revolute">
    <origin
      xyz="-0.00056116 0.0035 0.041997"
      rpy="0 -2.0194E-05 0" />
    <parent
      link="middle_link1" />
    <child
      link="middle_link2" />
    <axis
      xyz="0 1 0" />
    <limit
      lower="0"
      upper="1.57"
      effort="100"
      velocity="1" />
  </joint>
  <link
    name="middle_link3">
    <inertial>
      <origin
        xyz="-0.00202898234042185 -0.00838464237677725 -0.105427170323188"
        rpy="0 0 0" />
      <mass
        value="0.269152839443886" />
      <inertia
        ixx="0.00177766434388304"
        ixy="-6.07150463278799E-05"
        ixz="4.00607257485019E-05"
        iyy="0.00147732829998058"
        iyz="0.000145227139685572"
        izz="0.000428251027826904" />
    </inertial>
    <visual>
      <origin
        xyz="0 0 0"
        rpy="0 0 0" />
      <geometry>
        <mesh
          filename="meshes/middle_link3.STL" />
      </geometry>
      <material
        name="">
        <color
          rgba="1 1 1 1" />
      </material>
    </visual>
    <collision>
      <origin
        xyz="0 0 0"
        rpy="0 0 0" />
      <geometry>
        <mesh
          filename="meshes/middle_link3.STL" />
      </geometry>
    </collision>
  </link>
  <joint
    name="middle_joint3"
    type="revolute">
    <origin
      xyz="-0.002743 0 0.044215"
      rpy="0 0 0" />
    <parent
      link="middle_link2" />
    <child
      link="middle_link3" />
    <axis
      xyz="0 1 0" />
    <limit
      lower="0"
      upper="1.57"
      effort="100"
      velocity="1" />
  </joint>
  <link
    name="middle_link4">
    <inertial>
      <origin
        xyz="-0.000349704869523938 -7.4578572797912E-07 5.33973445394076E-05"
        rpy="0 0 0" />
      <mass
        value="1.25E-07" />
      <inertia
        ixx="5.20833333333332E-15"
        ixy="3.87023168072014E-29"
        ixz="5.53743377610218E-30"
        iyy="5.20833333333342E-15"
        iyz="1.21268865032447E-29"
        izz="5.20833333333335E-15" />
    </inertial>
    <visual>
      <origin
        xyz="0 0 0"
        rpy="0 0 0" />
      <geometry>
        <mesh
          filename="meshes/middle_link4.STL" />
      </geometry>
      <material
        name="">
        <color
          rgba="1 1 1 1" />
      </material>
    </visual>
    <collision>
      <origin
        xyz="0 0 0"
        rpy="0 0 0" />
      <geometry>
        <mesh
          filename="meshes/middle_link4.STL" />
      </geometry>
    </collision>
  </link>
  <joint
    name="middle_joint4"
    type="fixed">
    <origin
      xyz="-0.0126773959122548 -0.00599972219724709 0.0437367152831721"
      rpy="0 0 0" />
    <parent
      link="middle_link3" />
    <child
      link="middle_link4" />
    <axis
      xyz="0 0 0" />
  </joint>
  <link
    name="ring_link0">
    <inertial>
      <origin
        xyz="-0.0112077785389183 0.0202152553078928 0.0071599509520778"
        rpy="0 0 0" />
      <mass
        value="0.269152839443886" />
      <inertia
        ixx="0.00177830707271652"
        ixy="-5.93234165997825E-05"
        ixz="2.71290797017276E-05"
        iyy="0.00147732918866887"
        iyz="0.00014580189695368"
        izz="0.000427607410305141" />
    </inertial>
    <visual>
      <origin
        xyz="0 0 0"
        rpy="0 0 0" />
      <geometry>
        <mesh
          filename="meshes/ring_link0.STL" />
      </geometry>
      <material
        name="">
        <color
          rgba="1 1 1 1" />
      </material>
    </visual>
    <collision>
      <origin
        xyz="0 0 0"
        rpy="0 0 0" />
      <geometry>
        <mesh
          filename="meshes/ring_link0.STL" />
      </geometry>
    </collision>
  </link>
  <joint
    name="ring_joint0"
    type="revolute">
    <origin
      xyz="0.013795 -0.011295 0.13221"
      rpy="0.0026856 0 0" />
    <parent
      link="base_link" />
    <child
      link="ring_link0" />
    <axis
      xyz="1 0 0" />
    <limit
      lower="0"
      upper="0.18"
      effort="100"
      velocity="1" />
  </joint>
  <link
    name="ring_link1">
    <inertial>
      <origin
        xyz="-0.00501043638848299 0.0177152553079935 -0.0100619791966741"
        rpy="0 0 0" />
      <mass
        value="0.269152839443886" />
      <inertia
        ixx="0.00177566145718129"
        ixy="-6.34577267157826E-05"
        ixz="6.55928326435769E-05"
        iyy="0.00147732918866887"
        iyz="0.000144050608580546"
        izz="0.000430253025840368" />
    </inertial>
    <visual>
      <origin
        xyz="0 0 0"
        rpy="0 0 0" />
      <geometry>
        <mesh
          filename="meshes/ring_link1.STL" />
      </geometry>
      <material
        name="">
        <color
          rgba="1 1 1 1" />
      </material>
    </visual>
    <collision>
      <origin
        xyz="0 0 0"
        rpy="0 0 0" />
      <geometry>
        <mesh
          filename="meshes/ring_link1.STL" />
      </geometry>
    </collision>
  </link>
  <joint
    name="ring_joint1"
    type="revolute">
    <origin
      xyz="-0.0059124 0.0025 0.017075"
      rpy="0 0.028525 0" />
    <parent
      link="ring_link0" />
    <child
      link="ring_link1" />
    <axis
      xyz="0 1 0" />
    <limit
      lower="0"
      upper="1.57"
      effort="100"
      velocity="1" />
  </joint>
  <link
    name="ring_link2">
    <inertial>
      <origin
        xyz="-0.00445033006575546 0.0142152552987778 -0.0520584376961807"
        rpy="0 0 0" />
      <mass
        value="0.269152839443886" />
      <inertia
        ixx="0.00177566410577584"
        ixy="-6.34548177690244E-05"
        ixz="6.55656636040719E-05"
        iyy="0.00147732918867022"
        iyz="0.000144051890007602"
        izz="0.00043025037724447" />
    </inertial>
    <visual>
      <origin
        xyz="0 0 0"
        rpy="0 0 0" />
      <geometry>
        <mesh
          filename="meshes/ring_link2.STL" />
      </geometry>
      <material
        name="">
        <color
          rgba="1 1 1 1" />
      </material>
    </visual>
    <collision>
      <origin
        xyz="0 0 0"
        rpy="0 0 0" />
      <geometry>
        <mesh
          filename="meshes/ring_link2.STL" />
      </geometry>
    </collision>
  </link>
  <joint
    name="ring_joint2"
    type="revolute">
    <origin
      xyz="-0.00056116 0.0035 0.041997"
      rpy="0 -2.0194E-05 0" />
    <parent
      link="ring_link1" />
    <child
      link="ring_link2" />
    <axis
      xyz="0 1 0" />
    <limit
      lower="0"
      upper="1.57"
      effort="100"
      velocity="1" />
  </joint>
  <link
    name="ring_link3">
    <inertial>
      <origin
        xyz="-0.000744056113606869 0.0142152552972555 -0.0962856947299341"
        rpy="0 0 0" />
      <mass
        value="0.269152839443886" />
      <inertia
        ixx="0.0017742176306046"
        ixy="-6.48927865170148E-05"
        ixz="7.9011844091808E-05"
        iyy="0.0014773291886702"
        iyz="0.000143409857300473"
        izz="0.000431696852415732" />
    </inertial>
    <visual>
      <origin
        xyz="0 0 0"
        rpy="0 0 0" />
      <geometry>
        <mesh
          filename="meshes/ring_link3.STL" />
      </geometry>
      <material
        name="">
        <color
          rgba="1 1 1 1" />
      </material>
    </visual>
    <collision>
      <origin
        xyz="0 0 0"
        rpy="0 0 0" />
      <geometry>
        <mesh
          filename="meshes/ring_link3.STL" />
      </geometry>
    </collision>
  </link>
  <joint
    name="ring_joint3"
    type="revolute">
    <origin
      xyz="-0.002743 0 0.044215"
      rpy="0 0.010005 0" />
    <parent
      link="ring_link2" />
    <child
      link="ring_link3" />
    <axis
      xyz="0 1 0" />
    <limit
      lower="0"
      upper="1.57"
      effort="100"
      velocity="1" />
  </joint>
  <link
    name="ring_link4">
    <inertial>
      <origin
        xyz="-0.000349704869524039 -7.45785706329771E-07 5.33973445393521E-05"
        rpy="0 0 0" />
      <mass
        value="1.24999999999997E-07" />
      <inertia
        ixx="5.20833333333312E-15"
        ixy="-1.56062827940593E-29"
        ixz="6.55370848915644E-29"
        iyy="5.20833333333329E-15"
        iyz="-5.78853771655365E-29"
        izz="5.20833333333316E-15" />
    </inertial>
    <visual>
      <origin
        xyz="0 0 0"
        rpy="0 0 0" />
      <geometry>
        <mesh
          filename="meshes/ring_link4.STL" />
      </geometry>
      <material
        name="">
        <color
          rgba="1 1 1 1" />
      </material>
    </visual>
    <collision>
      <origin
        xyz="0 0 0"
        rpy="0 0 0" />
      <geometry>
        <mesh
          filename="meshes/ring_link4.STL" />
      </geometry>
    </collision>
  </link>
  <joint
    name="ring_joint4"
    type="fixed">
    <origin
      xyz="-0.0126773959122548 -0.0059997221972472 0.0437367152831721"
      rpy="0 0 0" />
    <parent
      link="ring_link3" />
    <child
      link="ring_link4" />
    <axis
      xyz="0 0 0" />
  </joint>
  <link
    name="little_link0">
    <inertial>
      <origin
        xyz="-0.0107436441658412 0.0428153673335656 0.0202102525407014"
        rpy="0 0 0" />
      <mass
        value="0.269152839443886" />
      <inertia
        ixx="0.00177870430091372"
        ixy="-5.79188233097981E-05"
        ixz="1.41579791394582E-05"
        iyy="0.00147732829997939"
        iyz="0.00014636478011374"
        izz="0.000427211070797417" />
    </inertial>
    <visual>
      <origin
        xyz="0 0 0"
        rpy="0 0 0" />
      <geometry>
        <mesh
          filename="meshes/little_link0.STL" />
      </geometry>
      <material
        name="">
        <color
          rgba="1 1 1 1" />
      </material>
    </visual>
    <collision>
      <origin
        xyz="0 0 0"
        rpy="0 0 0" />
      <geometry>
        <mesh
          filename="meshes/little_link0.STL" />
      </geometry>
    </collision>
  </link>
  <joint
    name="little_joint0"
    type="revolute">
    <origin
      xyz="0.013525 -0.03386 0.1192"
      rpy="0.0026858 -0.0095978 -2.5781E-05" />
    <parent
      link="base_link" />
    <child
      link="little_link0" />
    <axis
      xyz="1 0 0" />
    <limit
      lower="0"
      upper="0.18"
      effort="100"
      velocity="1" />
  </joint>
  <link
    name="little_link1">
    <inertial>
      <origin
        xyz="-0.00535748950691302 0.0407415104772609 0.00325808418821283"
        rpy="0 0 0" />
      <mass
        value="0.269152839443886" />
      <inertia
        ixx="0.00177830797201457"
        ixy="-5.93211342638309E-05"
        ixz="2.71279767150518E-05"
        iyy="0.00147732829997952"
        iyz="0.000145802064392169"
        izz="0.00042760739969644" />
    </inertial>
    <visual>
      <origin
        xyz="0 0 0"
        rpy="0 0 0" />
      <geometry>
        <mesh
          filename="meshes/little_link1.STL" />
      </geometry>
      <material
        name="">
        <color
          rgba="1 1 1 1" />
      </material>
    </visual>
    <collision>
      <origin
        xyz="0 0 0"
        rpy="0 0 0" />
      <geometry>
        <mesh
          filename="meshes/little_link1.STL" />
      </geometry>
    </collision>
  </link>
  <joint
    name="little_joint1"
    type="revolute">
    <origin
      xyz="-0.0054177 0.0020739 0.016901"
      rpy="0 0.0095993 0" />
    <parent
      link="little_link0" />
    <child
      link="little_link1" />
    <axis
      xyz="0 1 0" />
    <limit
      lower="0"
      upper="1.57"
      effort="100"
      velocity="1" />
  </joint>
  <link
    name="little_link2">
    <inertial>
      <origin
        xyz="-0.00478993701934439 0.0368153673294238 -0.0389124529640016"
        rpy="0 0 0" />
      <mass
        value="0.269152839443886" />
      <inertia
        ixx="0.00177830797201457"
        ixy="-5.93211342638289E-05"
        ixz="2.71279767150392E-05"
        iyy="0.00147732829997952"
        iyz="0.000145802064392158"
        izz="0.000427607399696436" />
    </inertial>
    <visual>
      <origin
        xyz="0 0 0"
        rpy="0 0 0" />
      <geometry>
        <mesh
          filename="meshes/little_link2.STL" />
      </geometry>
      <material
        name="">
        <color
          rgba="1 1 1 1" />
      </material>
    </visual>
    <collision>
      <origin
        xyz="0 0 0"
        rpy="0 0 0" />
      <geometry>
        <mesh
          filename="meshes/little_link2.STL" />
      </geometry>
    </collision>
  </link>
  <joint
    name="little_joint2"
    type="revolute">
    <origin
      xyz="-0.00056755 0.0039261 0.042171"
      rpy="0 0 0" />
    <parent
      link="little_link1" />
    <child
      link="little_link2" />
    <axis
      xyz="0 1 0" />
    <limit
      lower="0"
      upper="1.57"
      effort="100"
      velocity="1" />
  </joint>
  <link
    name="little_link3">
    <inertial>
      <origin
        xyz="0.000784355295522267 0.0382613536337701 -0.0825192173202409"
        rpy="0 0 0" />
      <mass
        value="0.269152839443886" />
      <inertia
        ixx="0.00177561171305537"
        ixy="-6.46550062862099E-05"
        ixz="6.49912386916088E-05"
        iyy="0.00147198294155489"
        iyz="0.000162208979298413"
        izz="0.000435649017080279" />
    </inertial>
    <visual>
      <origin
        xyz="0 0 0"
        rpy="0 0 0" />
      <geometry>
        <mesh
          filename="meshes/little_link3.STL" />
      </geometry>
      <material
        name="">
        <color
          rgba="1 1 1 1" />
      </material>
    </visual>
    <collision>
      <origin
        xyz="0 0 0"
        rpy="0 0 0" />
      <geometry>
        <mesh
          filename="meshes/little_link3.STL" />
      </geometry>
    </collision>
  </link>
  <joint
    name="little_joint3"
    type="revolute">
    <origin
      xyz="-0.0031697 0 0.04425"
      rpy="-0.017453 0.02891 0" />
    <parent
      link="little_link2" />
    <child
      link="little_link3" />
    <axis
      xyz="0 0.99985 0.017452" />
    <limit
      lower="0"
      upper="1.57"
      effort="100"
      velocity="1" />
  </joint>
  <link
    name="little_link4">
    <inertial>
      <origin
        xyz="-0.000349704869519324 -1.67759814370672E-06 5.33761957042661E-05"
        rpy="0 0 0" />
      <mass
        value="1.24999999999999E-07" />
      <inertia
        ixx="5.20833333333328E-15"
        ixy="-7.32373379952134E-30"
        ixz="-6.97648863054832E-30"
        iyy="5.20833333333331E-15"
        iyz="6.25865241055767E-29"
        izz="5.20833333333331E-15" />
    </inertial>
    <visual>
      <origin
        xyz="0 0 0"
        rpy="0 0 0" />
      <geometry>
        <mesh
          filename="meshes/little_link4.STL" />
      </geometry>
      <material
        name="">
        <color
          rgba="1 1 1 1" />
      </material>
    </visual>
    <collision>
      <origin
        xyz="0 0 0"
        rpy="0 0 0" />
      <geometry>
        <mesh
          filename="meshes/little_link4.STL" />
      </geometry>
    </collision>
  </link>
  <joint
    name="little_joint4"
    type="fixed">
    <origin
      xyz="-0.0122498806169438 -0.00676173621814952 0.0436028417314645"
      rpy="0 0 0" />
    <parent
      link="little_link3" />
    <child
      link="little_link4" />
    <axis
      xyz="0 0 0" />
  </joint>
</robot>