<mujoco model="linker_hand_l20_left">
    <compiler angle="radian" />
    <size njmax="500" nconmax="100" />
    <asset>
        <!-- 蓝白棋盘纹理 -->
        <texture name="grid_tex" type="2d" builtin="checker" rgb1="0.2 0.3 0.8" rgb2="1 1 1" width="512" height="512"/>
        
        <!-- 关联纹理的材质 -->
        <material name="grid_material" texture="grid_tex" texrepeat="10 10" specular="0.3" shininess="0.5"/>
        <mesh name="base_link" file="base_link.STL" />
        <mesh name="thumb_link0" file="thumb_link0.STL" />
        <mesh name="thumb_link1" file="thumb_link1.STL" />
        <mesh name="thumb_link2" file="thumb_link2.STL" />
        <mesh name="thumb_link3" file="thumb_link3.STL" />
        <mesh name="thumb_link4" file="thumb_link4.STL" />
        <mesh name="thumb_link5" file="thumb_link5.STL" />
        <mesh name="index_link0" file="index_link0.STL" />
        <mesh name="index_link1" file="index_link1.STL" />
        <mesh name="index_link2" file="index_link2.STL" />
        <mesh name="index_link3" file="index_link3.STL" />
        <mesh name="index_link4" file="index_link4.STL" />
        <mesh name="middle_link0" file="middle_link0.STL" />
        <mesh name="middle_link1" file="middle_link1.STL" />
        <mesh name="middle_link2" file="middle_link2.STL" />
        <mesh name="middle_link3" file="middle_link3.STL" />
        <mesh name="middle_link4" file="middle_link4.STL" />
        <mesh name="ring_link0" file="ring_link0.STL" />
        <mesh name="ring_link1" file="ring_link1.STL" />
        <mesh name="ring_link2" file="ring_link2.STL" />
        <mesh name="ring_link3" file="ring_link3.STL" />
        <mesh name="ring_link4" file="ring_link4.STL" />
        <mesh name="little_link0" file="little_link0.STL" />
        <mesh name="little_link1" file="little_link1.STL" />
        <mesh name="little_link2" file="little_link2.STL" />
        <mesh name="little_link3" file="little_link3.STL" />
        <mesh name="little_link4" file="little_link4.STL" />
    </asset>
    <visual>
        <quality shadowsize="4096"/>
        <map znear="0.05"/>
        <global offwidth="1280" offheight="720"/>
    </visual>

    <default>
        <joint limited="true" damping="0.1" armature="0.01"/>
        <motor ctrllimited="true"/>
        <geom condim="3" contype="1" conaffinity="1" solref="0.01 1" solimp="0.9 0.95 0.001" friction="1.0 0.005 0.0001"/>
        <equality solref="0.01 1"/>
    </default>
    <worldbody>
    <!-- 蓝白方格地面 -->
        <geom 
        name="floor" 
        type="plane" 
        pos="0 0 -0.01" 
        size="5 5 0.1" 
        material="grid_material"
        conaffinity="1" 
        condim="3"
        />
        <light directional="true" diffuse=".4 .4 .4" specular=".1 .1 .1" pos="0 0 5" dir="0 0 -1"/>
        <geom type="mesh" rgba="1 1 1 1" mesh="base_link" />
        <body name="thumb_link0" pos="-0.0025188 -0.0050821 0.052292">
            <inertial pos="0.0127888 -0.0025056 0.0016311" quat="0.714728 0.653385 0.198173 -0.151588" mass="0.002748" diaginertia="3.03396e-07 2.76444e-07 9.59657e-08" />
            <joint name="thumb_joint0" pos="0 0 0" axis="-1 0 0" limited="true" range="-0.297 0.683" />
            <geom type="mesh" rgba="1 1 1 1" mesh="thumb_link0" />
            <body name="thumb_link1" pos="0.024508 -0.00083332 -0.00845">
                <inertial pos="-0.00106505 -0.0129271 0.00955894" quat="0.821578 0.569398 0.0261064 0.0106998" mass="0.00188076" diaginertia="3.41494e-07 2.93718e-07 7.44231e-08" />
                <joint name="thumb_joint1" pos="0 0 0" axis="0 0 1" limited="true" range="0.122 1.78" />
                <geom type="mesh" rgba="1 1 1 1" mesh="thumb_link1" />
                <body name="thumb_link2" pos="0.010985 -0.030795 0.012414">
                    <inertial pos="-0.0106242 -0.0208034 0.0161575" quat="0.882449 0.470244 -0.00244079 0.0121843" mass="0.0205071" diaginertia="8.50825e-06 7.63476e-06 1.80325e-06" />
                    <joint name="thumb_joint2" pos="0 0 0" axis="-1 0 0" limited="true" range="0 0.87" />
                    <geom type="mesh" rgba="1 1 1 1" mesh="thumb_link2" />
                    <body name="thumb_link3" pos="-0.0010999 -0.044701 0.034112">
                        <inertial pos="-0.00937367 -0.0118165 0.00400539" quat="0.92791 0.372735 0.00539991 0.00476082" mass="0.00483281" diaginertia="6.14158e-07 4.65849e-07 1.99093e-07" />
                        <joint name="thumb_joint3" pos="0 0 0" axis="-1 0 0" limited="true" range="0 1.29" />
                        <geom type="mesh" rgba="1 1 1 1" mesh="thumb_link3" />
                        <body name="thumb_link4" pos="-0.01277 -0.030981 0.015322">
                            <inertial pos="0.00305603 -0.0105449 0.00593707" quat="0.787919 0.615769 0.00295912 -0.00185785" mass="0.00657183" diaginertia="5.94643e-07 5.28775e-07 1.63999e-07" />
                            <joint name="thumb_joint4" pos="0 0 0" axis="-1 0 0" limited="true" range="0 1.29" />
                            <geom type="mesh" rgba="1 1 1 1" mesh="thumb_link4" />
                            <geom pos="0.0040254 -0.030887 0.0073227" type="mesh" rgba="1 1 1 1" mesh="thumb_link5" />
                        </body>
                    </body>
                </body>
            </body>
        </body>
        <body name="index_link0" pos="-0.025865 -0.026698 0.15421">
            <inertial pos="0.00582427 5.50368e-07 0.0022475" quat="0.355185 0.355185 -0.611427 0.611427" mass="0.000858839" diaginertia="4.34042e-08 3.21335e-08 2.50587e-08" />
            <joint name="index_joint0" pos="0 0 0" axis="1 0 0" limited="true" range="-0.26 0.26" />
            <geom type="mesh" rgba="1 1 1 1" mesh="index_link0" />
            <body name="index_link1" pos="0.011115 -0.0047959 0">
                <inertial pos="-0.000683356 0.0048078 0.0243018" quat="0.707512 -0.00568475 -0.00587904 0.706654" mass="0.00458484" diaginertia="7.20266e-07 7.10515e-07 1.385e-07" />
                <joint name="index_joint1" pos="0 0 0" axis="0 1 0" limited="true" range="0 1.4" />
                <geom type="mesh" rgba="1 1 1 1" mesh="index_link1" />
                <body name="index_link2" pos="-0.0034454 0.0010465 0.044883">
                    <inertial pos="0.00281619 0.00381383 0.0165996" quat="0.999163 2.62805e-05 0.0409006 -6.95714e-05" mass="0.00240942" diaginertia="2.39031e-07 1.8348e-07 9.72399e-08" />
                    <joint name="index_joint2" pos="0 0 0" axis="0 1 0" limited="true" range="0 1.08" />
                    <geom type="mesh" rgba="1 1 1 1" mesh="index_link2" />
                    <body name="index_link3" pos="0.0084126 -0.0012 0.03069">
                        <inertial pos="-0.00677812 0.00520866 0.00972347" quat="0.992008 3.57322e-05 -0.126178 -0.000280925" mass="0.00356381" diaginertia="2.50693e-07 2.44047e-07 1.13074e-07" />
                        <joint name="index_joint3" pos="0 0 0" axis="0 1 0" limited="true" range="0 1.15" />
                        <geom type="mesh" rgba="1 1 1 1" mesh="index_link3" />
                        <geom pos="-0.013709 0.0063957 0.024981" type="mesh" rgba="1 1 1 1" mesh="index_link4" />
                    </body>
                </body>
            </body>
        </body>
        <body name="middle_link0" pos="-0.030599 -0.0050984 0.1587">
            <inertial pos="0.00582427 5.60656e-07 0.0022475" quat="0.355185 0.355185 -0.611427 0.611427" mass="0.000858839" diaginertia="4.34042e-08 3.21335e-08 2.50587e-08" />
            <joint name="middle_joint0" pos="0 0 0" axis="1 0 0" limited="true" range="-0.26 0.26" />
            <geom type="mesh" rgba="1 1 1 1" mesh="middle_link0" />
            <body name="middle_link1" pos="0.011115 -0.0047959 0">
                <inertial pos="-0.000683358 0.00480779 0.0243018" quat="0.707512 -0.00568485 -0.00587906 0.706654" mass="0.00458484" diaginertia="7.20267e-07 7.10516e-07 1.385e-07" />
                <joint name="middle_joint1" pos="0 0 0" axis="0 1 0" limited="true" range="0 1.4" />
                <geom type="mesh" rgba="1 1 1 1" mesh="middle_link1" />
                <body name="middle_link2" pos="-0.0034454 0.0010465 0.044883">
                    <inertial pos="0.00281619 0.00381383 0.0165996" quat="0.999163 2.62805e-05 0.0409006 -6.95714e-05" mass="0.00240942" diaginertia="2.39031e-07 1.8348e-07 9.72399e-08" />
                    <joint name="middle_joint2" pos="0 0 0" axis="0 1 0" limited="true" range="0 1.08" />
                    <geom type="mesh" rgba="1 1 1 1" mesh="middle_link2" />
                    <body name="middle_link3" pos="0.0084126 -0.0012 0.03069">
                        <inertial pos="-0.00677812 0.00520866 0.00972347" quat="0.992008 3.57659e-05 -0.126178 -0.00028119" mass="0.00356381" diaginertia="2.50693e-07 2.44047e-07 1.13074e-07" />
                        <joint name="middle_joint3" pos="0 0 0" axis="0 1 0" limited="true" range="0 1.15" />
                        <geom type="mesh" rgba="1 1 1 1" mesh="middle_link3" />
                        <geom pos="-0.013709 0.0063957 0.024981" type="mesh" rgba="1 1 1 1" mesh="middle_link4" />
                    </body>
                </body>
            </body>
        </body>
        <body name="ring_link0" pos="-0.028294 0.016502 0.15421">
            <inertial pos="0.00582427 5.60656e-07 0.0022475" quat="0.355185 0.355185 -0.611427 0.611427" mass="0.000858839" diaginertia="4.34042e-08 3.21335e-08 2.50587e-08" />
            <joint name="ring_joint0" pos="0 0 0" axis="1 0 0" limited="true" range="-0.26 0.26" />
            <geom type="mesh" rgba="1 1 1 1" mesh="ring_link0" />
            <body name="ring_link1" pos="0.011115 -0.0047959 0">
                <inertial pos="-0.000683358 0.0048078 0.0243018" quat="0.707513 -0.00568489 -0.0058791 0.706653" mass="0.00458484" diaginertia="7.20267e-07 7.10516e-07 1.385e-07" />
                <joint name="ring_joint1" pos="0 0 0" axis="0 1 0" limited="true" range="0 1.4" />
                <geom type="mesh" rgba="1 1 1 1" mesh="ring_link1" />
                <body name="ring_link2" pos="-0.0034454 0.0010465 0.044883">
                    <inertial pos="0.00281619 0.00381383 0.0165996" quat="0.999163 2.62805e-05 0.0409006 -6.95714e-05" mass="0.00240942" diaginertia="2.39031e-07 1.8348e-07 9.72399e-08" />
                    <joint name="ring_joint2" pos="0 0 0" axis="0 1 0" limited="true" range="0 1.08" />
                    <geom type="mesh" rgba="1 1 1 1" mesh="ring_link2" />
                    <body name="ring_link3" pos="0.0084126 -0.0012 0.03069">
                        <inertial pos="-0.00677812 0.00520865 0.00972345" quat="0.992008 3.56333e-05 -0.126178 -0.000280147" mass="0.00356381" diaginertia="2.50693e-07 2.44048e-07 1.13074e-07" />
                        <joint name="ring_joint3" pos="0 0 0" axis="0 1 0" limited="true" range="0 1.15" />
                        <geom type="mesh" rgba="1 1 1 1" mesh="ring_link3" />
                        <geom pos="-0.013709 0.0063957 0.024981" type="mesh" rgba="1 1 1 1" mesh="ring_link4" />
                    </body>
                </body>
            </body>
        </body>
        <body name="little_link0" pos="-0.02467 0.038102 0.14521">
            <inertial pos="0.00582427 5.60668e-07 0.0022475" quat="0.355185 0.355185 -0.611427 0.611427" mass="0.000858839" diaginertia="4.34042e-08 3.21335e-08 2.50587e-08" />
            <joint name="little_joint0" pos="0 0 0" axis="1 0 0" limited="true" range="-0.26 0.26" />
            <geom type="mesh" rgba="1 1 1 1" mesh="little_link0" />
            <body name="little_link1" pos="0.011115 -0.0047959 0">
                <inertial pos="-0.000683358 0.0048078 0.0243018" quat="0.707513 -0.00568489 -0.0058791 0.706653" mass="0.00458484" diaginertia="7.20267e-07 7.10516e-07 1.385e-07" />
                <joint name="little_joint1" pos="0 0 0" axis="0 1 0" limited="true" range="0 1.4" />
                <geom type="mesh" rgba="1 1 1 1" mesh="little_link1" />
                <body name="little_link2" pos="-0.0034454 0.0010465 0.044883">
                    <inertial pos="0.00281619 0.00381383 0.0165996" quat="0.999163 2.62805e-05 0.0409006 -6.95714e-05" mass="0.00240942" diaginertia="2.39031e-07 1.8348e-07 9.72399e-08" />
                    <joint name="little_joint2" pos="0 0 0" axis="0 1 0" limited="true" range="0 1.08" />
                    <geom type="mesh" rgba="1 1 1 1" mesh="little_link2" />
                    <body name="little_link3" pos="0.0084126 -0.0012 0.03069">
                        <inertial pos="-0.00677812 0.00520865 0.00972346" quat="0.992008 3.57829e-05 -0.126178 -0.000281324" mass="0.00356381" diaginertia="2.50694e-07 2.44048e-07 1.13074e-07" />
                        <joint name="little_joint3" pos="0 0 0" axis="0 1 0" limited="true" range="0 1.15" />
                        <geom type="mesh" rgba="1 1 1 1" mesh="little_link3" />
                        <geom pos="-0.013709 0.0063957 0.024981" type="mesh" rgba="1 1 1 1" mesh="little_link4" />
                    </body>
                </body>
            </body>
        </body>
    </worldbody>
    <!-- 
    Joint 0: thumb_joint0
    Joint 1: thumb_joint1
    Joint 2: thumb_joint2
    Joint 3: thumb_joint3
    Joint 4: thumb_joint4
    Joint 5: index_joint0
    Joint 6: index_joint1
    Joint 7: index_joint2
    Joint 8: index_joint3
    Joint 9: middle_joint0
    Joint 10: middle_joint1
    Joint 11: middle_joint2
    Joint 12: middle_joint3
    Joint 13: ring_joint0
    Joint 14: ring_joint1
    Joint 15: ring_joint2
    Joint 16: ring_joint3
    Joint 17: little_joint0
    Joint 18: little_joint1
    Joint 19: little_joint2
    Joint 20: little_joint3 
    -->
    <actuator>
        <position name="thumb_pos0" joint="thumb_joint0" kp="10" ctrlrange="-0.297 0.683"/>
        <position name="thumb_pos1" joint="thumb_joint1" kp="10" ctrlrange="0.122 1.78"/>
        <position name="thumb_pos2" joint="thumb_joint2" kp="10" ctrlrange="0 0.87"/>
        <position name="thumb_pos3" joint="thumb_joint3" kp="10" ctrlrange="0 1.29"/>
        <position name="thumb_pos4" joint="thumb_joint4" kp="10" ctrlrange="0 1.29"/>
        
        <position name="index_pos0" joint="index_joint0" kp="10" ctrlrange="-0.26 0.26"/>
        <position name="index_pos1" joint="index_joint1" kp="10" ctrlrange="0 1.4"/>
        <position name="index_pos2" joint="index_joint2" kp="10" ctrlrange="0 1.08"/>
        <position name="index_pos3" joint="index_joint3" kp="10" ctrlrange="0 1.15"/>
        
        <position name="middle_pos0" joint="middle_joint0" kp="10" ctrlrange="-0.26 0.26"/>
        <position name="middle_pos1" joint="middle_joint1" kp="10" ctrlrange="0 1.4"/>
        <position name="middle_pos2" joint="middle_joint2" kp="10" ctrlrange="0 1.08"/>
        <position name="middle_pos3" joint="middle_joint3" kp="10" ctrlrange="0 1.15"/>

        
        <position name="ring_pos0" joint="ring_joint0" kp="10" ctrlrange="-0.26 0.26"/>
        <position name="ring_pos1" joint="ring_joint1" kp="10" ctrlrange="0 1.4"/>
        <position name="ring_pos2" joint="ring_joint2" kp="10" ctrlrange="0 1.08"/>
        <position name="ring_pos3" joint="ring_joint3" kp="10" ctrlrange="0 1.15"/>
        
        <position name="little_pos0" joint="little_joint0" kp="10" ctrlrange="-0.26 0.26"/>
        <position name="little_pos1" joint="little_joint1" kp="10" ctrlrange="0 1.4"/>
        <position name="little_pos2" joint="little_joint2" kp="10" ctrlrange="0 1.08"/>
        <position name="little_pos3" joint="little_joint3" kp="10" ctrlrange="0 1.15"/>
    </actuator>
</mujoco>
