<?xml version="1.0" encoding="utf-8"?>
<!-- This URDF was automatically created by SolidWorks to URDF Exporter! Originally created by Stephen Brawner (brawner@gmail.com) 
     Commit Version: 1.6.0-4-g7f85cfe  Build Version: 1.6.7995.38578
     For more information, please see http://wiki.ros.org/sw_urdf_exporter -->
<robot
  name="steering_1_l">
  <link
    name="base_link">
    <inertial>
      <origin
        xyz="0.00049108 -0.0037208 0.030813"
        rpy="0 0 0" />
      <mass
        value="0.033428" />
      <inertia
        ixx="1.6389E-05"
        ixy="7.4502E-09"
        ixz="-1.0143E-07"
        iyy="7.3765E-06"
        iyz="2.4685E-07"
        izz="1.0269E-05" />
    </inertial>
    <visual>
      <origin
        xyz="0 0 0"
        rpy="0 0 0" />
      <geometry>
        <mesh
          filename="package://steering_1_l/meshes/base_link.STL" />
      </geometry>
      <material
        name="">
        <color
          rgba="0.5 0.5 0.5 1" />
      </material>
    </visual>
    <collision>
      <origin
        xyz="0 0 0"
        rpy="0 0 0" />
      <geometry>
        <mesh
          filename="package://steering_1_l/meshes/base_link.STL" />
      </geometry>
    </collision>
  </link>
  <link
    name="thumb_link0">
    <inertial>
      <origin
        xyz="0.012102 0.010666 0.0022128"
        rpy="0 0 0" />
      <mass
        value="0.0033788" />
      <inertia
        ixx="5.1233E-07"
        ixy="-5.1956E-08"
        ixz="-1.4105E-08"
        iyy="1.7872E-07"
        iyz="2.1857E-08"
        izz="5.8581E-07" />
    </inertial>
    <visual>
      <origin
        xyz="0 0 0"
        rpy="0 0 0" />
      <geometry>
        <mesh
          filename="package://steering_1_l/meshes/thumb_link0.STL" />
      </geometry>
      <material
        name="">
        <color
          rgba="1 1 1 1" />
      </material>
    </visual>
    <collision>
      <origin
        xyz="0 0 0"
        rpy="0 0 0" />
      <geometry>
        <mesh
          filename="package://steering_1_l/meshes/thumb_link0.STL" />
      </geometry>
    </collision>
  </link>
  <joint
    name="thumb_joint"
    type="revolute">
    <origin
      xyz="0.011 -0.02613 0.022"
      rpy="0 0 0" />
    <parent
      link="base_link" />
    <child
      link="thumb_link0" />
    <axis
      xyz="1 0 0" />
    <limit
      lower="-1.57"
      upper="1.57"
      effort="100"
      velocity="1" />
  </joint>
  <link
    name="thumb_link1">
    <inertial>
      <origin
        xyz="0.011088 -3.2033E-05 -0.02402"
        rpy="0 0 0" />
      <mass
        value="0.011598" />
      <inertia
        ixx="7.3564E-07"
        ixy="-5.3014E-11"
        ixz="1.9318E-08"
        iyy="1.3663E-06"
        iyz="-2.6856E-11"
        izz="9.1142E-07" />
    </inertial>
    <visual>
      <origin
        xyz="0 0 0"
        rpy="0 0 0" />
      <geometry>
        <mesh
          filename="package://steering_1_l/meshes/thumb_link1.STL" />
      </geometry>
      <material
        name="">
        <color
          rgba="1 1 1 1" />
      </material>
    </visual>
    <collision>
      <origin
        xyz="0 0 0"
        rpy="0 0 0" />
      <geometry>
        <mesh
          filename="package://steering_1_l/meshes/thumb_link1.STL" />
      </geometry>
    </collision>
  </link>
  <joint
    name="thumb_joint1"
    type="revolute">
    <origin
      xyz="0.0153 -0.0128 0.0112"
      rpy="0 0 0" />
    <parent
      link="thumb_link0" />
    <child
      link="thumb_link1" />
    <axis
      xyz="0 0 1" />
    <limit
      lower="-0.75"
      upper="0.5"
      effort="100"
      velocity="1" />
  </joint>
  <link
    name="thumb_link2">
    <inertial>
      <origin
        xyz="0.012825 -0.0098858 0.029555"
        rpy="0 0 0" />
      <mass
        value="0.011732" />
      <inertia
        ixx="8.975E-07"
        ixy="2.6856E-11"
        ixz="-2.6252E-08"
        iyy="1.3787E-06"
        iyz="-5.3014E-11"
        izz="6.9452E-07" />
    </inertial>
    <visual>
      <origin
        xyz="0 0 0"
        rpy="0 0 0" />
      <geometry>
        <mesh
          filename="package://steering_1_l/meshes/thumb_link2.STL" />
      </geometry>
      <material
        name="">
        <color
          rgba="1 1 1 1" />
      </material>
    </visual>
    <collision>
      <origin
        xyz="0 0 0"
        rpy="0 0 0" />
      <geometry>
        <mesh
          filename="package://steering_1_l/meshes/thumb_link2.STL" />
      </geometry>
    </collision>
  </link>
  <joint
    name="thumb_joint2"
    type="revolute">
    <origin
      xyz="0.0147 0.00985 -0.0114"
      rpy="0 0 0" />
    <parent
      link="thumb_link1" />
    <child
      link="thumb_link2" />
    <axis
      xyz="0 1 0" />
    <limit
      lower="-0.06"
      upper="1.77"
      effort="100"
      velocity="1" />
  </joint>
  <link
    name="thumb_link3">
    <inertial>
      <origin
        xyz="0.012825 -0.0098858 0.029555"
        rpy="0 0 0" />
      <mass
        value="0.011732" />
      <inertia
        ixx="8.975E-07"
        ixy="2.6856E-11"
        ixz="-2.6252E-08"
        iyy="1.3787E-06"
        iyz="-5.3014E-11"
        izz="6.9452E-07" />
    </inertial>
    <visual>
      <origin
        xyz="0 0 0"
        rpy="0 0 0" />
      <geometry>
        <mesh
          filename="package://steering_1_l/meshes/thumb_link3.STL" />
      </geometry>
      <material
        name="">
        <color
          rgba="1 1 1 1" />
      </material>
    </visual>
    <collision>
      <origin
        xyz="0 0 0"
        rpy="0 0 0" />
      <geometry>
        <mesh
          filename="package://steering_1_l/meshes/thumb_link3.STL" />
      </geometry>
    </collision>
  </link>
  <joint
    name="thumb_joint3"
    type="revolute">
    <origin
      xyz="0 0 0.0342"
      rpy="0 0 0" />
    <parent
      link="thumb_link2" />
    <child
      link="thumb_link3" />
    <axis
      xyz="0 1 0" />
    <limit
      lower="-2.28"
      upper="0.2"
      effort="100"
      velocity="1" />
  </joint>
  <link
    name="thumb_link4">
    <inertial>
      <origin
        xyz="-0.000798356098793633 -0.00999998346601536 0.0231547999463213"
        rpy="0 0 0" />
      <mass
        value="0.00462415260078596" />
      <inertia
        ixx="3.24617477346335E-07"
        ixy="4.59687783829023E-13"
        ixz="4.04753165713766E-08"
        iyy="3.742787777534E-07"
        iyz="-1.14074800355316E-12"
        izz="1.49646859988098E-07" />
    </inertial>
    <visual>
      <origin
        xyz="0 0 0"
        rpy="0 0 0" />
      <geometry>
        <mesh
          filename="package://steering_1_l/meshes/thumb_link4.STL" />
      </geometry>
      <material
        name="">
        <color
          rgba="1 1 1 1" />
      </material>
    </visual>
    <collision>
      <origin
        xyz="0 0 0"
        rpy="0 0 0" />
      <geometry>
        <mesh
          filename="package://steering_1_l/meshes/thumb_link4.STL" />
      </geometry>
    </collision>
  </link>
  <joint
    name="thumb_joint4"
    type="revolute">
    <origin
      xyz="0 0.0001 0.0342"
      rpy="0 0 0" />
    <parent
      link="thumb_link3" />
    <child
      link="thumb_link4" />
    <axis
      xyz="0 1 0" />
    <limit
      lower="-2.3"
      upper="0.16"
      effort="100"
      velocity="1" />
  </joint>
  <link
    name="thumb_link5">
    <inertial>
      <origin
        xyz="0 -0.001 0"
        rpy="0 0 0" />
      <mass
        value="1.5707963267949E-06" />
      <inertia
        ixx="6.21773546022978E-13"
        ixy="7.47414175780256E-30"
        ixz="-2.52233723578467E-44"
        iyy="1.96349540849362E-13"
        iyz="8.97389961772669E-29"
        izz="6.21773546022978E-13" />
    </inertial>
    <visual>
      <origin
        xyz="0 0 0"
        rpy="0 0 0" />
      <geometry>
        <mesh
          filename="package://steering_1_l/meshes/thumb_link5.STL" />
      </geometry>
      <material
        name="">
        <color
          rgba="1 1 1 1" />
      </material>
    </visual>
    <collision>
      <origin
        xyz="0 0 0"
        rpy="0 0 0" />
      <geometry>
        <mesh
          filename="package://steering_1_l/meshes/thumb_link5.STL" />
      </geometry>
    </collision>
  </link>
  <joint
    name="thumb_joint5"
    type="fixed">
    <origin
      xyz="-0.00713 -0.0091 0.041674"
      rpy="0 0 0" />
    <parent
      link="thumb_link4" />
    <child
      link="thumb_link5" />
    <axis
      xyz="0 0 0" />
    <limit
      lower="0"
      upper="0"
      effort="0"
      velocity="0" />
  </joint>
  <link
    name="index_link0">
    <inertial>
      <origin
        xyz="-0.0244117026775088 -6.20153657063961E-05 0.00331644935502975"
        rpy="0 0 0" />
      <mass
        value="0.011382106718867" />
      <inertia
        ixx="9.02611352200267E-07"
        ixy="2.68563181955561E-11"
        ixz="1.66882853102769E-08"
        iyy="1.35553332862216E-06"
        iyz="5.3014025877215E-11"
        izz="7.31896912750044E-07" />
    </inertial>
    <visual>
      <origin
        xyz="0 0 0"
        rpy="0 0 0" />
      <geometry>
        <mesh
          filename="package://steering_1_l/meshes/index_link0.STL" />
      </geometry>
      <material
        name="">
        <color
          rgba="1 1 1 1" />
      </material>
    </visual>
    <collision>
      <origin
        xyz="0 0 0"
        rpy="0 0 0" />
      <geometry>
        <mesh
          filename="package://steering_1_l/meshes/index_link0.STL" />
      </geometry>
    </collision>
  </link>
  <joint
    name="index_joint0"
    type="revolute">
    <origin
      xyz="0.0147 -0.032 0.0758"
      rpy="0 0 0" />
    <parent
      link="base_link" />
    <child
      link="index_link0" />
    <axis
      xyz="1 0 0" />
    <limit
      lower="-0.68"
      upper="0.68"
      effort="100"
      velocity="1" />
  </joint>
  <link
    name="index_link1">
    <inertial>
      <origin
        xyz="-0.0128251150413257 -0.00991424875096365 0.0295551835629555"
        rpy="0 0 0" />
      <mass
        value="0.0117322172918848" />
      <inertia
        ixx="8.97496889350237E-07"
        ixy="2.68555604003543E-11"
        ixz="2.62517989023823E-08"
        iyy="1.37868813091978E-06"
        iyz="5.30140258772299E-11"
        izz="6.94524351821246E-07" />
    </inertial>
    <visual>
      <origin
        xyz="0 0 0"
        rpy="0 0 0" />
      <geometry>
        <mesh
          filename="package://steering_1_l/meshes/index_link1.STL" />
      </geometry>
      <material
        name="">
        <color
          rgba="1 1 1 1" />
      </material>
    </visual>
    <collision>
      <origin
        xyz="0 0 0"
        rpy="0 0 0" />
      <geometry>
        <mesh
          filename="package://steering_1_l/meshes/index_link1.STL" />
      </geometry>
    </collision>
  </link>
  <joint
    name="index_joint1"
    type="revolute">
    <origin
      xyz="-0.0114 0.00985 0.0067"
      rpy="0 0 0" />
    <parent
      link="index_link0" />
    <child
      link="index_link1" />
    <axis
      xyz="0 1 0" />
    <limit
      lower="-0.2"
      upper="2.28"
      effort="100"
      velocity="1" />
  </joint>
  <link
    name="index_link2">
    <inertial>
      <origin
        xyz="-0.0128251150413257 -0.00991424875096366 0.0295551835629555"
        rpy="0 0 0" />
      <mass
        value="0.0117322172918848" />
      <inertia
        ixx="8.97496889350237E-07"
        ixy="2.68555604004725E-11"
        ixz="2.62517989023826E-08"
        iyy="1.37868813091978E-06"
        iyz="5.30140258774053E-11"
        izz="6.94524351821246E-07" />
    </inertial>
    <visual>
      <origin
        xyz="0 0 0"
        rpy="0 0 0" />
      <geometry>
        <mesh
          filename="package://steering_1_l/meshes/index_link2.STL" />
      </geometry>
      <material
        name="">
        <color
          rgba="1 1 1 1" />
      </material>
    </visual>
    <collision>
      <origin
        xyz="0 0 0"
        rpy="0 0 0" />
      <geometry>
        <mesh
          filename="package://steering_1_l/meshes/index_link2.STL" />
      </geometry>
    </collision>
  </link>
  <joint
    name="index_joint2"
    type="revolute">
    <origin
      xyz="0 0 0.0342"
      rpy="0 0 0" />
    <parent
      link="index_link1" />
    <child
      link="index_link2" />
    <axis
      xyz="0 1 0" />
    <limit
      lower="-0.2"
      upper="2.28"
      effort="100"
      velocity="1" />
  </joint>
  <link
    name="index_link3">
    <inertial>
      <origin
        xyz="0.000798356098793613 -0.0100000165339847 0.0231547999463214"
        rpy="0 0 0" />
      <mass
        value="0.00462415260078597" />
      <inertia
        ixx="3.24617477346336E-07"
        ixy="4.59687783914108E-13"
        ixz="-4.04753165713768E-08"
        iyy="3.74278777753402E-07"
        iyz="1.14074800392339E-12"
        izz="1.49646859988098E-07" />
    </inertial>
    <visual>
      <origin
        xyz="0 0 0"
        rpy="0 0 0" />
      <geometry>
        <mesh
          filename="package://steering_1_l/meshes/index_link3.STL" />
      </geometry>
      <material
        name="">
        <color
          rgba="1 1 1 1" />
      </material>
    </visual>
    <collision>
      <origin
        xyz="0 0 0"
        rpy="0 0 0" />
      <geometry>
        <mesh
          filename="package://steering_1_l/meshes/index_link3.STL" />
      </geometry>
    </collision>
  </link>
  <joint
    name="index_joint3"
    type="revolute">
    <origin
      xyz="0 0.0001 0.0342"
      rpy="0 0 0" />
    <parent
      link="index_link2" />
    <child
      link="index_link3" />
    <axis
      xyz="0 1 0" />
    <limit
      lower="-0.16"
      upper="2.3"
      effort="100"
      velocity="1" />
  </joint>
  <link
    name="index_link4">
    <inertial>
      <origin
        xyz="-1.73472347597681E-18 -0.000999999999999999 0"
        rpy="0 0 0" />
      <mass
        value="1.5707963267949E-06" />
      <inertia
        ixx="6.2177354602298E-13"
        ixy="7.47414175780259E-30"
        ixz="-2.24207754291971E-44"
        iyy="1.96349540849362E-13"
        iyz="-8.71580963087833E-29"
        izz="6.2177354602298E-13" />
    </inertial>
    <visual>
      <origin
        xyz="0 0 0"
        rpy="0 0 0" />
      <geometry>
        <mesh
          filename="package://steering_1_l/meshes/index_link4.STL" />
      </geometry>
      <material
        name="">
        <color
          rgba="1 1 1 1" />
      </material>
    </visual>
    <collision>
      <origin
        xyz="0 0 0"
        rpy="0 0 0" />
      <geometry>
        <mesh
          filename="package://steering_1_l/meshes/index_link4.STL" />
      </geometry>
    </collision>
  </link>
  <joint
    name="index_joint4"
    type="fixed">
    <origin
      xyz="0.00713 -0.0089 0.041674"
      rpy="0 0 0" />
    <parent
      link="index_link3" />
    <child
      link="index_link4" />
    <axis
      xyz="0 0 0" />
  </joint>
  <link
    name="middle_link0">
    <inertial>
      <origin
        xyz="-0.0244117026775088 -6.20153657063978E-05 0.00331644935502975"
        rpy="0 0 0" />
      <mass
        value="0.011382106718867" />
      <inertia
        ixx="9.02611352200267E-07"
        ixy="2.68563181955066E-11"
        ixz="1.6688285310277E-08"
        iyy="1.35553332862215E-06"
        iyz="5.30140258771094E-11"
        izz="7.31896912750043E-07" />
    </inertial>
    <visual>
      <origin
        xyz="0 0 0"
        rpy="0 0 0" />
      <geometry>
        <mesh
          filename="package://steering_1_l/meshes/middle_link0.STL" />
      </geometry>
      <material
        name="">
        <color
          rgba="1 1 1 1" />
      </material>
    </visual>
    <collision>
      <origin
        xyz="0 0 0"
        rpy="0 0 0" />
      <geometry>
        <mesh
          filename="package://steering_1_l/meshes/middle_link0.STL" />
      </geometry>
    </collision>
  </link>
  <joint
    name="middle_joint0"
    type="revolute">
    <origin
      xyz="0.0147 0 0.0758"
      rpy="0 0 0" />
    <parent
      link="base_link" />
    <child
      link="middle_link0" />
    <axis
      xyz="1 0 0" />
    <limit
      lower="-0.68"
      upper="0.68"
      effort="100"
      velocity="1" />
  </joint>
  <link
    name="middle_link1">
    <inertial>
      <origin
        xyz="-0.0128251150413256 -0.00991424875096365 0.0295551835629555"
        rpy="0 0 0" />
      <mass
        value="0.0117322172918848" />
      <inertia
        ixx="8.97496889350237E-07"
        ixy="2.68555604003391E-11"
        ixz="2.62517989023825E-08"
        iyy="1.37868813091978E-06"
        iyz="5.30140258771403E-11"
        izz="6.94524351821246E-07" />
    </inertial>
    <visual>
      <origin
        xyz="0 0 0"
        rpy="0 0 0" />
      <geometry>
        <mesh
          filename="package://steering_1_l/meshes/middle_link1.STL" />
      </geometry>
      <material
        name="">
        <color
          rgba="1 1 1 1" />
      </material>
    </visual>
    <collision>
      <origin
        xyz="0 0 0"
        rpy="0 0 0" />
      <geometry>
        <mesh
          filename="package://steering_1_l/meshes/middle_link1.STL" />
      </geometry>
    </collision>
  </link>
  <joint
    name="middle_joint1"
    type="revolute">
    <origin
      xyz="-0.0114 0.00985 0.0067"
      rpy="0 0 0" />
    <parent
      link="middle_link0" />
    <child
      link="middle_link1" />
    <axis
      xyz="0 1 0" />
    <limit
      lower="-0.2"
      upper="2.28"
      effort="100"
      velocity="1" />
  </joint>
  <link
    name="middle_link2">
    <inertial>
      <origin
        xyz="-0.0128251150413257 -0.00991424875096366 0.0295551835629555"
        rpy="0 0 0" />
      <mass
        value="0.0117322172918848" />
      <inertia
        ixx="8.97496889350237E-07"
        ixy="2.68555604003561E-11"
        ixz="2.62517989023827E-08"
        iyy="1.37868813091978E-06"
        iyz="5.30140258774002E-11"
        izz="6.94524351821245E-07" />
    </inertial>
    <visual>
      <origin
        xyz="0 0 0"
        rpy="0 0 0" />
      <geometry>
        <mesh
          filename="package://steering_1_l/meshes/middle_link2.STL" />
      </geometry>
      <material
        name="">
        <color
          rgba="1 1 1 1" />
      </material>
    </visual>
    <collision>
      <origin
        xyz="0 0 0"
        rpy="0 0 0" />
      <geometry>
        <mesh
          filename="package://steering_1_l/meshes/middle_link2.STL" />
      </geometry>
    </collision>
  </link>
  <joint
    name="middle_joint2"
    type="revolute">
    <origin
      xyz="0 0 0.0342"
      rpy="0 0 0" />
    <parent
      link="middle_link1" />
    <child
      link="middle_link2" />
    <axis
      xyz="0 1 0" />
    <limit
      lower="-0.2"
      upper="2.28"
      effort="100"
      velocity="1" />
  </joint>
  <link
    name="middle_link3">
    <inertial>
      <origin
        xyz="0.000798356098793612 -0.0100000165339847 0.0231547999463214"
        rpy="0 0 0" />
      <mass
        value="0.00462415260078596" />
      <inertia
        ixx="3.24617477346336E-07"
        ixy="4.59687783877438E-13"
        ixz="-4.04753165713768E-08"
        iyy="3.74278777753401E-07"
        iyz="1.1407480038273E-12"
        izz="1.49646859988098E-07" />
    </inertial>
    <visual>
      <origin
        xyz="0 0 0"
        rpy="0 0 0" />
      <geometry>
        <mesh
          filename="package://steering_1_l/meshes/middle_link3.STL" />
      </geometry>
      <material
        name="">
        <color
          rgba="1 1 1 1" />
      </material>
    </visual>
    <collision>
      <origin
        xyz="0 0 0"
        rpy="0 0 0" />
      <geometry>
        <mesh
          filename="package://steering_1_l/meshes/middle_link3.STL" />
      </geometry>
    </collision>
  </link>
  <joint
    name="middle_joint3"
    type="revolute">
    <origin
      xyz="0 0.0001 0.0342"
      rpy="0 0 0" />
    <parent
      link="middle_link2" />
    <child
      link="middle_link3" />
    <axis
      xyz="0 1 0" />
    <limit
      lower="-0.16"
      upper="2.3"
      effort="100"
      velocity="1" />
  </joint>
  <link
    name="middle_link4">
    <inertial>
      <origin
        xyz="-1.73472347597681E-18 -0.001 0"
        rpy="0 0 0" />
      <mass
        value="1.5707963267949E-06" />
      <inertia
        ixx="6.21773546022981E-13"
        ixy="7.47414175780282E-30"
        ixz="-2.24207754291971E-44"
        iyy="1.96349540849362E-13"
        iyz="-7.53502081644822E-29"
        izz="6.21773546022981E-13" />
    </inertial>
    <visual>
      <origin
        xyz="0 0 0"
        rpy="0 0 0" />
      <geometry>
        <mesh
          filename="package://steering_1_l/meshes/middle_link4.STL" />
      </geometry>
      <material
        name="">
        <color
          rgba="1 1 1 1" />
      </material>
    </visual>
    <collision>
      <origin
        xyz="0 0 0"
        rpy="0 0 0" />
      <geometry>
        <mesh
          filename="package://steering_1_l/meshes/middle_link4.STL" />
      </geometry>
    </collision>
  </link>
  <joint
    name="middle_joint4"
    type="fixed">
    <origin
      xyz="0.00713 -0.0089 0.041674"
      rpy="0 0 0" />
    <parent
      link="middle_link3" />
    <child
      link="middle_link4" />
    <axis
      xyz="0 0 0" />
  </joint>
  <link
    name="ring_link0">
    <inertial>
      <origin
        xyz="0 0 0"
        rpy="0 0 0" />
      <mass
        value="0" />
      <inertia
        ixx="0"
        ixy="0"
        ixz="0"
        iyy="0"
        iyz="0"
        izz="0" />
    </inertial>
    <visual>
      <origin
        xyz="0 0 0"
        rpy="0 0 0" />
      <geometry>
        <mesh
          filename="package://steering_1_l/meshes/ring_link0.STL" />
      </geometry>
      <material
        name="">
        <color
          rgba="1 1 1 1" />
      </material>
    </visual>
    <collision>
      <origin
        xyz="0 0 0"
        rpy="0 0 0" />
      <geometry>
        <mesh
          filename="package://steering_1_l/meshes/ring_link0.STL" />
      </geometry>
    </collision>
  </link>
  <joint
    name="ring_joint0"
    type="revolute">
    <origin
      xyz="0.0147 0.032 0.0758"
      rpy="0 0 0" />
    <parent
      link="base_link" />
    <child
      link="ring_link0" />
    <axis
      xyz="1 0 0" />
    <limit
      lower="-0.68"
      upper="0.68"
      effort="100"
      velocity="1" />
  </joint>
  <link
    name="ring_link1">
    <inertial>
      <origin
        xyz="-0.0128251150413256 -0.00991424875096366 0.0295551835629555"
        rpy="0 0 0" />
      <mass
        value="0.0117322172918848" />
      <inertia
        ixx="8.97496889350237E-07"
        ixy="2.68555604002911E-11"
        ixz="2.62517989023825E-08"
        iyy="1.37868813091978E-06"
        iyz="5.30140258771839E-11"
        izz="6.94524351821246E-07" />
    </inertial>
    <visual>
      <origin
        xyz="0 0 0"
        rpy="0 0 0" />
      <geometry>
        <mesh
          filename="package://steering_1_l/meshes/ring_link1.STL" />
      </geometry>
      <material
        name="">
        <color
          rgba="1 1 1 1" />
      </material>
    </visual>
    <collision>
      <origin
        xyz="0 0 0"
        rpy="0 0 0" />
      <geometry>
        <mesh
          filename="package://steering_1_l/meshes/ring_link1.STL" />
      </geometry>
    </collision>
  </link>
  <joint
    name="ring_joint1"
    type="revolute">
    <origin
      xyz="-0.0114 0.00985 0.0067"
      rpy="0 0 0" />
    <parent
      link="ring_link0" />
    <child
      link="ring_link1" />
    <axis
      xyz="0 1 0" />
    <limit
      lower="-0.2"
      upper="2.28"
      effort="100"
      velocity="1" />
  </joint>
  <link
    name="ring_link2">
    <inertial>
      <origin
        xyz="-0.0128251150413257 -0.00991424875096368 0.0295551835629555"
        rpy="0 0 0" />
      <mass
        value="0.0117322172918848" />
      <inertia
        ixx="8.97496889350237E-07"
        ixy="2.68555604003224E-11"
        ixz="2.62517989023826E-08"
        iyy="1.37868813091978E-06"
        iyz="5.30140258775195E-11"
        izz="6.94524351821245E-07" />
    </inertial>
    <visual>
      <origin
        xyz="0 0 0"
        rpy="0 0 0" />
      <geometry>
        <mesh
          filename="package://steering_1_l/meshes/ring_link2.STL" />
      </geometry>
      <material
        name="">
        <color
          rgba="1 1 1 1" />
      </material>
    </visual>
    <collision>
      <origin
        xyz="0 0 0"
        rpy="0 0 0" />
      <geometry>
        <mesh
          filename="package://steering_1_l/meshes/ring_link2.STL" />
      </geometry>
    </collision>
  </link>
  <joint
    name="ring_joint2"
    type="revolute">
    <origin
      xyz="0 0 0.0342"
      rpy="0 0 0" />
    <parent
      link="ring_link1" />
    <child
      link="ring_link2" />
    <axis
      xyz="0 1 0" />
    <limit
      lower="-0.2"
      upper="2.28"
      effort="100"
      velocity="1" />
  </joint>
  <link
    name="ring_link3">
    <inertial>
      <origin
        xyz="0.000798356098793614 -0.0100000165339847 0.0231547999463214"
        rpy="0 0 0" />
      <mass
        value="0.00462415260078596" />
      <inertia
        ixx="3.24617477346335E-07"
        ixy="4.59687783886547E-13"
        ixz="-4.04753165713767E-08"
        iyy="3.74278777753401E-07"
        iyz="1.14074800384477E-12"
        izz="1.49646859988098E-07" />
    </inertial>
    <visual>
      <origin
        xyz="0 0 0"
        rpy="0 0 0" />
      <geometry>
        <mesh
          filename="package://steering_1_l/meshes/ring_link3.STL" />
      </geometry>
      <material
        name="">
        <color
          rgba="1 1 1 1" />
      </material>
    </visual>
    <collision>
      <origin
        xyz="0 0 0"
        rpy="0 0 0" />
      <geometry>
        <mesh
          filename="package://steering_1_l/meshes/ring_link3.STL" />
      </geometry>
    </collision>
  </link>
  <joint
    name="ring_joint3"
    type="revolute">
    <origin
      xyz="0 0.0001 0.0342"
      rpy="0 0 0" />
    <parent
      link="ring_link2" />
    <child
      link="ring_link3" />
    <axis
      xyz="0 1 0" />
    <limit
      lower="-0.16"
      upper="2.3"
      effort="100"
      velocity="1" />
  </joint>
  <link
    name="ring_link4">
    <inertial>
      <origin
        xyz="0 -0.00100000000000001 0"
        rpy="0 0 0" />
      <mass
        value="1.5707963267949E-06" />
      <inertia
        ixx="6.21773546022981E-13"
        ixy="7.47414175780269E-30"
        ixz="-1.96181785005474E-44"
        iyy="1.96349540849362E-13"
        iyz="1.01768114000019E-28"
        izz="6.21773546022981E-13" />
    </inertial>
    <visual>
      <origin
        xyz="0 0 0"
        rpy="0 0 0" />
      <geometry>
        <mesh
          filename="package://steering_1_l/meshes/ring_link4.STL" />
      </geometry>
      <material
        name="">
        <color
          rgba="1 1 1 1" />
      </material>
    </visual>
    <collision>
      <origin
        xyz="0 0 0"
        rpy="0 0 0" />
      <geometry>
        <mesh
          filename="package://steering_1_l/meshes/ring_link4.STL" />
      </geometry>
    </collision>
  </link>
  <joint
    name="ring_joint4"
    type="fixed">
    <origin
      xyz="0.00713 -0.0089 0.041674"
      rpy="0 0 0" />
    <parent
      link="ring_link3" />
    <child
      link="ring_link4" />
    <axis
      xyz="0 0 0" />
  </joint>
</robot>