<mujoco model="linker_hand_l20_right">
    <compiler angle="radian" />
    <size njmax="500" nconmax="100" />
    <asset>
        <!-- 蓝白棋盘纹理 -->
        <texture name="grid_tex" type="2d" builtin="checker" rgb1="0.2 0.3 0.8" rgb2="1 1 1" width="512" height="512"/>
        
        <!-- 关联纹理的材质 -->
        <material name="grid_material" texture="grid_tex" texrepeat="10 10" specular="0.3" shininess="0.5"/>
        <mesh name="base_link" file="base_link.STL" />
        <mesh name="thumb_link0" file="thumb_link0.STL" />
        <mesh name="thumb_link1" file="thumb_link1.STL" />
        <mesh name="thumb_link2" file="thumb_link2.STL" />
        <mesh name="thumb_link3" file="thumb_link3.STL" />
        <mesh name="thumb_link4" file="thumb_link4.STL" />
        <mesh name="thumb_link5" file="thumb_link5.STL" />
        <mesh name="index_link0" file="index_link0.STL" />
        <mesh name="index_link1" file="index_link1.STL" />
        <mesh name="index_link2" file="index_link2.STL" />
        <mesh name="index_link3" file="index_link3.STL" />
        <mesh name="index_link4" file="index_link4.STL" />
        <mesh name="middle_link0" file="middle_link0.STL" />
        <mesh name="middle_link1" file="middle_link1.STL" />
        <mesh name="middle_link2" file="middle_link2.STL" />
        <mesh name="middle_link3" file="middle_link3.STL" />
        <mesh name="middle_link4" file="middle_link4.STL" />
        <mesh name="ring_link0" file="ring_link0.STL" />
        <mesh name="ring_link1" file="ring_link1.STL" />
        <mesh name="ring_link2" file="ring_link2.STL" />
        <mesh name="ring_link3" file="ring_link3.STL" />
        <mesh name="ring_link4" file="ring_link4.STL" />
        <mesh name="little_link0" file="little_link0.STL" />
        <mesh name="little_link1" file="little_link1.STL" />
        <mesh name="little_link2" file="little_link2.STL" />
        <mesh name="little_link3" file="little_link3.STL" />
        <mesh name="little_link4" file="little_link4.STL" />
    </asset>
    <visual>
        <quality shadowsize="4096"/>
        <map znear="0.05"/>
        <global offwidth="1280" offheight="720"/>
    </visual>

    <default>
        <joint limited="true" damping="0.1" armature="0.01"/>
        <motor ctrllimited="true"/>
        <geom condim="3" contype="1" conaffinity="1" solref="0.01 1" solimp="0.9 0.95 0.001" friction="1.0 0.005 0.0001"/>
        <equality solref="0.01 1"/>
    </default>
    <worldbody>
    <!-- 蓝白方格地面 -->
        <geom 
        name="floor" 
        type="plane" 
        pos="0 0 -0.01" 
        size="5 5 0.1" 
        material="grid_material"
        conaffinity="1" 
        condim="3"
        />
        <light directional="true" diffuse=".4 .4 .4" specular=".1 .1 .1" pos="0 0 5" dir="0 0 -1"/>
        <geom type="mesh" rgba="1 1 1 1" mesh="base_link" />
        <body name="thumb_link0" pos="-0.0025189 0.0050821 0.052292">
            <inertial pos="0.0127889 0.00250561 0.00163117" quat="0.653382 0.714726 0.1516 -0.198183" mass="0.00274798" diaginertia="3.03393e-07 2.76443e-07 9.59634e-08" />
            <joint name="thumb_joint0" pos="0 0 0" axis="1 0 0" limited="true" range="-0.297 0.683" />
            <geom type="mesh" rgba="1 1 1 1" mesh="thumb_link0" />
            <body name="thumb_link1" pos="0.024705 0.00083336 -0.00445" quat="0.99699 0 -0.0775271 0">
                <inertial pos="-0.000388191 0.0129265 0.00568707" quat="0.568511 0.817082 0.0334716 -0.0897315" mass="0.00188085" diaginertia="3.41513e-07 2.93738e-07 7.44257e-08" />
                <joint name="thumb_joint1" pos="0 0 0" axis="0 0 -1" limited="true" range="0 1.78" />
                <geom type="mesh" rgba="0.4 0.4 0.4 1" mesh="thumb_link1" />
                <body name="thumb_link2" pos="0.011959 0.030795 0.0066455" quat="0.99699 0 0.0775271 0">
                    <inertial pos="-0.0106232 0.0208042 0.0161569" quat="0.470265 0.88244 -0.0120243 0.00236009" mass="0.0205094" diaginertia="8.50901e-06 7.63494e-06 1.80403e-06" />
                    <joint name="thumb_joint2" pos="0 0 0" axis="1 0 0" limited="true" range="0 0.87" />
                    <geom type="mesh" rgba="1 1 1 1" mesh="thumb_link2" />
                    <body name="thumb_link3" pos="-0.0011 0.044701 0.034112">
                        <inertial pos="-0.00937364 0.0118164 0.00400538" quat="0.92791 -0.372734 0.00539935 -0.00475844" mass="0.00483279" diaginertia="6.14155e-07 4.65847e-07 1.99092e-07" />
                        <joint name="thumb_joint3" pos="0 0 0" axis="1 0 0" limited="true" range="0 1.29" />
                        <geom type="mesh" rgba="1 1 1 1" mesh="thumb_link3" />
                        <body name="thumb_link4" pos="-0.01277 0.030981 0.015322">
                            <inertial pos="0.00305557 0.0105449 0.00593725" quat="0.615789 0.787904 0.00180099 -0.00288585" mass="0.0065722" diaginertia="5.94673e-07 5.28797e-07 1.64011e-07" />
                            <joint name="thumb_joint4" pos="0 0 0" axis="1 0 0" limited="true" range="0 1.29" />
                            <geom type="mesh" rgba="1 1 1 1" mesh="thumb_link4" />
                            <geom pos="0.0040253 0.030887 0.0073227" type="mesh" rgba="1 1 1 1" mesh="thumb_link5" />
                        </body>
                    </body>
                </body>
            </body>
        </body>
        <body name="index_link0" pos="-0.028565 0.026698 0.15421">
            <inertial pos="0.00852427 -5.482e-07 0.0022475" quat="0.355185 0.355185 -0.611427 0.611427" mass="0.000858839" diaginertia="4.34042e-08 3.21335e-08 2.50587e-08" />
            <joint name="index_joint0" pos="0 0 0" axis="1 0 0" limited="true" range="-0.26 0.26" />
            <geom type="mesh" rgba="1 1 1 1" mesh="index_link0" />
            <body name="index_link1" pos="0.013815 0.0047959 0" quat="0.999965 0 0.0083524 0">
                <inertial pos="-0.00107024 -0.00480727 0.0231537" quat="0.706498 -0.0117917 -0.0115837 0.707522" mass="0.00458484" diaginertia="7.20269e-07 7.10518e-07 1.38501e-07" />
                <joint name="index_joint1" pos="0 0 0" axis="0 1 0" limited="true" range="0 1.4" />
                <geom type="mesh" rgba="1 1 1 1" mesh="index_link1" />
                <body name="index_link2" pos="-0.0041946 -0.0024865 0.044819" quat="0.999965 0 -0.0083524 0">
                    <inertial pos="0.00281611 -0.0023741 0.0165998" quat="0.999163 -4.77578e-05 0.0408972 9.28897e-05" mass="0.00240934" diaginertia="2.39021e-07 1.83473e-07 9.72368e-08" />
                    <joint name="index_joint2" pos="0 0 0" axis="0 1 0" limited="true" range="0 1.08" />
                    <geom type="mesh" rgba="1 1 1 1" mesh="index_link2" />
                    <body name="index_link3" pos="0.0084126 0.0056405 0.03069">
                        <inertial pos="-0.00677777 -0.00820941 0.00972138" quat="0.992007 -1.34653e-05 -0.126185 0.000105857" mass="0.00356312" diaginertia="2.50587e-07 2.4395e-07 1.1308e-07" />
                        <joint name="index_joint3" pos="0 0 0" axis="0 1 0" limited="true" range="0 1.15" />
                        <geom type="mesh" rgba="1 1 1 1" mesh="index_link3" />
                        <geom pos="-0.013709 -0.0073962 0.024981" type="mesh" rgba="1 1 1 1" mesh="index_link4" />
                    </body>
                </body>
            </body>
        </body>
        <body name="middle_link0" pos="-0.033299 0.0050984 0.1587">
            <inertial pos="0.00852427 -5.47869e-07 0.0022475" quat="0.355185 0.355185 -0.611427 0.611427" mass="0.000858839" diaginertia="4.34042e-08 3.21335e-08 2.50587e-08" />
            <joint name="middle_joint0" pos="0 0 0" axis="1 0 0" limited="true" range="-0.26 0.26" />
            <geom type="mesh" rgba="1 1 1 1" mesh="middle_link0" />
            <body name="middle_link1" pos="0.013815 0.0047959 0" quat="0.998134 0 0.061057 0">
                <inertial pos="-0.00350203 -0.00480727 0.0229123" quat="0.704904 -0.049073 -0.0488112 0.705917" mass="0.00458484" diaginertia="7.20269e-07 7.10518e-07 1.38501e-07" />
                <joint name="middle_joint1" pos="0 0 0" axis="0 1 0" limited="true" range="0 1.4" />
                <geom type="mesh" rgba="0.4 0.4 0.4 1" mesh="middle_link1" />
                <body name="middle_link2" pos="-0.0088902 -0.0024865 0.044129" quat="0.998134 0 -0.061057 0">
                    <inertial pos="0.00281611 -0.0023741 0.0165998" quat="0.999163 -4.77578e-05 0.0408972 9.28897e-05" mass="0.00240934" diaginertia="2.39021e-07 1.83473e-07 9.72368e-08" />
                    <joint name="middle_joint2" pos="0 0 0" axis="0 1 0" limited="true" range="0 1.08" />
                    <geom type="mesh" rgba="1 1 1 1" mesh="middle_link2" />
                    <body name="middle_link3" pos="0.0084126 0.0056405 0.03069">
                        <inertial pos="-0.00677777 -0.00820941 0.00972138" quat="0.992007 -1.33993e-05 -0.126186 0.000105338" mass="0.00356312" diaginertia="2.50587e-07 2.4395e-07 1.1308e-07" />
                        <joint name="middle_joint3" pos="0 0 0" axis="0 1 0" limited="true" range="0 1.15" />
                        <geom type="mesh" rgba="1 1 1 1" mesh="middle_link3" />
                        <geom pos="-0.013709 -0.0073962 0.024981" quat="0.996991 0 -0.0775172 0" type="mesh" rgba="1 1 1 1" mesh="middle_link4" />
                    </body>
                </body>
            </body>
        </body>
        <body name="ring_link0" pos="-0.030994 -0.016502 0.15421">
            <inertial pos="0.00852427 -5.482e-07 0.0022475" quat="0.355185 0.355185 -0.611427 0.611427" mass="0.000858839" diaginertia="4.34042e-08 3.21335e-08 2.50587e-08" />
            <joint name="ring_joint0" pos="0 0 0" axis="1 0 0" limited="true" range="-0.26 0.26" />
            <geom type="mesh" rgba="1 1 1 1" mesh="ring_link0" />
            <body name="ring_link1" pos="0.013815 0.0047959 0" quat="0.998134 0 0.061057 0">
                <inertial pos="-0.00350203 -0.00480727 0.0229123" quat="0.704904 -0.049073 -0.0488112 0.705917" mass="0.00458484" diaginertia="7.20269e-07 7.10518e-07 1.38501e-07" />
                <joint name="ring_joint1" pos="0 0 0" axis="0 1 0" limited="true" range="0 1.4" />
                <geom type="mesh" rgba="1 1 1 1" mesh="ring_link1" />
                <body name="ring_link2" pos="-0.0088902 -0.0024865 0.044129" quat="0.998134 0 -0.061057 0">
                    <inertial pos="0.00281611 -0.0023741 0.0165998" quat="0.999163 -4.77578e-05 0.0408972 9.28897e-05" mass="0.00240934" diaginertia="2.39021e-07 1.83473e-07 9.72368e-08" />
                    <joint name="ring_joint2" pos="0 0 0" axis="0 1 0" limited="true" range="0 1.08" />
                    <geom type="mesh" rgba="1 1 1 1" mesh="ring_link2" />
                    <body name="ring_link3" pos="0.0084126 0.0056405 0.03069">
                        <inertial pos="-0.00677777 -0.00820942 0.00972139" quat="0.992007 -1.3371e-05 -0.126185 0.000105116" mass="0.00356312" diaginertia="2.50588e-07 2.4395e-07 1.1308e-07" />
                        <joint name="ring_joint3" pos="0 0 0" axis="0 1 0" limited="true" range="0 1.15" />
                        <geom type="mesh" rgba="1 1 1 1" mesh="ring_link3" />
                        <geom pos="-0.013709 -0.0073962 0.024981" type="mesh" rgba="1 1 1 1" mesh="ring_link4" />
                    </body>
                </body>
            </body>
        </body>
        <body name="little_link0" pos="-0.02737 -0.038102 0.14521">
            <inertial pos="0.00852427 -5.47869e-07 0.0022475" quat="0.355185 0.355185 -0.611427 0.611427" mass="0.000858839" diaginertia="4.34042e-08 3.21335e-08 2.50587e-08" />
            <joint name="little_joint0" pos="0 0 0" axis="1 0 0" limited="true" range="-0.26 0.26" />
            <geom type="mesh" rgba="1 1 1 1" mesh="little_link0" />
            <body name="little_link1" pos="0.013815 0.0047959 0" quat="0.998134 0 0.061057 0">
                <inertial pos="-0.00350203 -0.00480727 0.0229123" quat="0.704904 -0.049073 -0.0488112 0.705917" mass="0.00458484" diaginertia="7.20269e-07 7.10518e-07 1.38501e-07" />
                <joint name="little_joint1" pos="0 0 0" axis="0 1 0" limited="true" range="0 1.4" />
                <geom type="mesh" rgba="1 1 1 1" mesh="little_link1" />
                <body name="little_link2" pos="-0.0088902 -0.0024865 0.044129" quat="0.998134 0 -0.061057 0">
                    <inertial pos="0.00281611 -0.0023741 0.0165998" quat="0.999163 -4.77578e-05 0.0408972 9.28897e-05" mass="0.00240934" diaginertia="2.39021e-07 1.83473e-07 9.72368e-08" />
                    <joint name="little_joint2" pos="0 0 0" axis="0 1 0" limited="true" range="0 1.08" />
                    <geom type="mesh" rgba="1 1 1 1" mesh="little_link2" />
                    <body name="little_link3" pos="0.0084126 0.0056405 0.03069">
                        <inertial pos="-0.00677777 -0.00820941 0.00972139" quat="0.992007 -1.28715e-05 -0.126186 0.000101189" mass="0.00356312" diaginertia="2.50588e-07 2.43951e-07 1.1308e-07" />
                        <joint name="little_joint3" pos="0 0 0" axis="0 1 0" limited="true" range="0 1.15" />
                        <geom type="mesh" rgba="1 1 1 1" mesh="little_link3" />
                        <geom pos="-0.013709 -0.0073962 0.024981" quat="0.996991 0 -0.0775172 0" type="mesh" rgba="1 1 1 1" mesh="little_link4" />
                    </body>
                </body>
            </body>
        </body>
    </worldbody>
    <actuator>
        <position name="thumb_pos0" joint="thumb_joint0" kp="10" ctrlrange="-0.297 0.683"/>
        <position name="thumb_pos1" joint="thumb_joint1" kp="10" ctrlrange="0.122 1.78"/>
        <position name="thumb_pos2" joint="thumb_joint2" kp="10" ctrlrange="0 0.87"/>
        <position name="thumb_pos3" joint="thumb_joint3" kp="10" ctrlrange="0 1.29"/>
        <position name="thumb_pos4" joint="thumb_joint4" kp="10" ctrlrange="0 1.29"/>
        
        <position name="index_pos0" joint="index_joint0" kp="10" ctrlrange="-0.26 0.26"/>
        <position name="index_pos1" joint="index_joint1" kp="10" ctrlrange="0 1.4"/>
        <position name="index_pos2" joint="index_joint2" kp="10" ctrlrange="0 1.08"/>
        <position name="index_pos3" joint="index_joint3" kp="10" ctrlrange="0 1.15"/>
        
        <position name="middle_pos0" joint="middle_joint0" kp="10" ctrlrange="-0.26 0.26"/>
        <position name="middle_pos1" joint="middle_joint1" kp="10" ctrlrange="0 1.4"/>
        <position name="middle_pos2" joint="middle_joint2" kp="10" ctrlrange="0 1.08"/>
        <position name="middle_pos3" joint="middle_joint3" kp="10" ctrlrange="0 1.15"/>

        
        <position name="ring_pos0" joint="ring_joint0" kp="10" ctrlrange="-0.26 0.26"/>
        <position name="ring_pos1" joint="ring_joint1" kp="10" ctrlrange="0 1.4"/>
        <position name="ring_pos2" joint="ring_joint2" kp="10" ctrlrange="0 1.08"/>
        <position name="ring_pos3" joint="ring_joint3" kp="10" ctrlrange="0 1.15"/>
        
        <position name="little_pos0" joint="little_joint0" kp="10" ctrlrange="-0.26 0.26"/>
        <position name="little_pos1" joint="little_joint1" kp="10" ctrlrange="0 1.4"/>
        <position name="little_pos2" joint="little_joint2" kp="10" ctrlrange="0 1.08"/>
        <position name="little_pos3" joint="little_joint3" kp="10" ctrlrange="0 1.15"/>
    </actuator>
</mujoco>
