<mujoco model="linkerhand_l21_left">
  <compiler angle="radian" autolimits="true"/>
  <statistic meansize="0.105831" extent="0.292216" center="-0.00403094 -0.0286347 0.122978"/>
  <size njmax="500" nconmax="100" />
  <asset>
    <!-- 蓝白棋盘纹理 -->
    <texture name="grid_tex" type="2d" builtin="checker" rgb1="0.2 0.3 0.8" rgb2="1 1 1" width="512" height="512"/>
    
    <!-- 关联纹理的材质 -->
    <material name="grid_material" texture="grid_tex" texrepeat="10 10" specular="0.3" shininess="0.5"/>
    <mesh name="hand_base_link" file="hand_base_link.STL"/>
    <mesh name="index_metacarpals" file="index_metacarpals.STL"/>
    <mesh name="index_proximal" file="index_proximal.STL"/>
    <mesh name="index_middle" file="index_middle.STL"/>
    <mesh name="middle_metacarpals" file="middle_metacarpals.STL"/>
    <mesh name="middle_proximal" file="middle_proximal.STL"/>
    <mesh name="middle_middle" file="middle_middle.STL"/>
    <mesh name="ring_metacarpals" file="ring_metacarpals.STL"/>
    <mesh name="ring_proximal" file="ring_proximal.STL"/>
    <mesh name="ring_middle" file="ring_middle.STL"/>
    <mesh name="pinky_metacarpals" file="pinky_metacarpals.STL"/>
    <mesh name="pinky_proximal" file="pinky_proximal.STL"/>
    <mesh name="pinky_middle" file="pinky_middle.STL"/>
    <mesh name="thumb_metacarpals_base1" file="thumb_metacarpals_base1.STL"/>
    <mesh name="thumb_metacarpals_base2" file="thumb_metacarpals_base2.STL"/>
    <mesh name="thumb_metacarpals" file="thumb_metacarpals.STL"/>
    <mesh name="thumb_proximal" file="thumb_proximal.STL"/>
    <mesh name="thumb_distal" file="thumb_distal.STL"/>
  </asset>
  <visual>
    <quality shadowsize="4096"/>
    <map znear="0.05"/>
    <global offwidth="1280" offheight="720"/>
  </visual>
  <default>
    <joint limited="true" damping="0.1" armature="0.01"/>
    <motor ctrllimited="true"/>
    <geom condim="3" contype="1" conaffinity="1" solref="0.01 1" solimp="0.9 0.95 0.001" friction="1.0 0.005 0.0001"/>
    <equality solref="0.01 1"/>
  </default>
  <worldbody>
    <!-- 蓝白方格地面 -->
    <geom 
    name="floor" 
    type="plane" 
    pos="0 0 0" 
    size="5 5 0.1" 
    material="grid_material"
    conaffinity="1" 
    condim="3"
    />
    <light directional="true" diffuse=".4 .4 .4" specular=".1 .1 .1" pos="0 0 5" dir="0 0 -1"/>
    <geom type="mesh" rgba="1 1 1 1" mesh="hand_base_link"/>
    <body name="index_metacarpals" pos="0.0059834 -0.032908 0.13338" quat="0.999996 -0.00283225 0 0">
      <inertial pos="0.0053256 0.0026647 -0.015279" quat="0.720857 0.691343 -0.0358855 0.0335095" mass="0.00041989" diaginertia="1.237e-08 7.47782e-09 5.56173e-09"/>
      <joint name="index_mcp_roll" pos="0 0 0" axis="1 0 0" range="0 0.18"/>
      <geom type="mesh" rgba="1 1 1 1" mesh="index_metacarpals"/>
      <body name="index_proximal" pos="0.002358 -0.00022359 0.018075">
        <inertial pos="0.008273 0.0206947 -0.0594112" quat="0.870583 0.455553 0.0434607 -0.180742" mass="0.0031019" diaginertia="7.25458e-06 5.10832e-06 2.59814e-06"/>
        <joint name="index_mcp_pitch" pos="0 0 0" axis="0 1 0" range="0 1.57"/>
        <geom type="mesh" rgba="1 1 1 1" mesh="index_proximal"/>
        <body name="index_middle" pos="-0.000158 0 0.044">
          <inertial pos="0.008431 0.020698 -0.103411" quat="0.870583 0.455553 0.0434607 -0.180742" mass="0.0031019" diaginertia="7.25458e-06 5.10832e-06 2.59814e-06"/>
          <joint name="index_pip" pos="0 0 0" axis="0 1 0" range="0 1.57"/>
          <geom type="mesh" rgba="1 1 1 1" mesh="index_middle"/>
        </body>
      </body>
    </body>
    <body name="middle_metacarpals" pos="0.0059834 -0.010766 0.14075" quat="0.999996 -0.00283225 0 0">
      <inertial pos="0.00809603 0.000967328 -0.0158492" quat="0.701888 0.710944 -0.0317263 0.0301004" mass="0.00048998" diaginertia="1.70887e-08 1.16047e-08 6.25161e-09"/>
      <joint name="middle_mcp_roll" pos="0 0 0" axis="1 0 0" range="-0.18 0.18"/>
      <geom type="mesh" rgba="1 1 1 1" mesh="middle_metacarpals"/>
      <body name="middle_proximal" pos="0.0023586 -0.0002236 0.018075">
        <inertial pos="0.00827259 -0.00140535 -0.0669112" quat="0.870583 0.455553 0.0434607 -0.180742" mass="0.0031019" diaginertia="7.25458e-06 5.10832e-06 2.59814e-06"/>
        <joint name="middle_mcp_pitch" pos="0 0 0" axis="0 1 0" range="0 1.57"/>
        <geom type="mesh" rgba="1 1 1 1" mesh="middle_proximal"/>
        <body name="middle_middle" pos="0.00044403 0 0.043998">
          <inertial pos="0.00782856 -0.00141465 -0.110909" quat="0.870583 0.455553 0.0434607 -0.180742" mass="0.0031019" diaginertia="7.25458e-06 5.10832e-06 2.59814e-06"/>
          <joint name="middle_pip" pos="0 0 0" axis="0 1 0" range="0 1.57"/>
          <geom type="mesh" rgba="1 1 1 1" mesh="middle_middle"/>
        </body>
      </body>
    </body>
    <body name="ring_metacarpals" pos="0.0059834 0.010791 0.13313" quat="0.999996 -0.00283225 0 0">
      <inertial pos="0.00568291 0.00100547 -0.0157135" quat="0.701581 0.71116 -0.0327294 0.0310398" mass="0.000471376" diaginertia="1.64167e-08 1.10964e-08 6.03918e-09"/>
      <joint name="ring_mcp_roll" pos="0 0 0" axis="1 0 0" range="-0.18 0.18"/>
      <geom type="mesh" rgba="1 1 1 1" mesh="ring_metacarpals"/>
      <body name="ring_proximal" pos="0.0023592 -0.0002236 0.018075">
        <inertial pos="0.00827217 -0.0230052 -0.0594112" quat="0.870583 0.455553 0.0434607 -0.180742" mass="0.0031019" diaginertia="7.25458e-06 5.10832e-06 2.59814e-06"/>
        <joint name="ring_mcp_pitch" pos="0 0 0" axis="0 1 0" range="0 1.57"/>
        <geom type="mesh" rgba="1 1 1 1" mesh="ring_proximal"/>
        <body name="ring_middle" pos="-0.000158 0 0.044">
          <inertial pos="0.00843017 -0.0230019 -0.103411" quat="0.870583 0.455553 0.0434607 -0.180742" mass="0.0031019" diaginertia="7.25458e-06 5.10832e-06 2.59814e-06"/>
          <joint name="ring_pip" pos="0 0 0" axis="0 1 0" range="0 1.57"/>
          <geom type="mesh" rgba="1 1 1 1" mesh="ring_middle"/>
        </body>
      </body>
    </body>
    <body name="pinky_metacarpals" pos="0.0059834 0.032806 0.11807" quat="0.999996 -0.00283225 0 0">
      <inertial pos="0.00770791 -0.000457499 -0.0154299" quat="0.667486 0.743078 -0.0348181 0.0329505" mass="0.00043626" diaginertia="1.28626e-08 7.84446e-09 5.73039e-09"/>
      <joint name="pinky_mcp_roll" pos="0 0 0" axis="-1 0 0" range="0 0.18"/>
      <geom type="mesh" rgba="1 1 1 1" mesh="pinky_metacarpals"/>
      <body name="pinky_proximal" pos="0.0023598 -0.0002236 0.018075">
        <inertial pos="0.00827175 -0.0451053 -0.0444733" quat="0.870583 0.455553 0.0434607 -0.180742" mass="0.0031019" diaginertia="7.25458e-06 5.10832e-06 2.59814e-06"/>
        <joint name="pinky_mcp_pitch" pos="0 0 0" axis="0 1 0" range="0 1.57"/>
        <geom type="mesh" rgba="1 1 1 1" mesh="pinky_proximal"/>
        <body name="pinky_middle" pos="-0.000158 0 0.044">
          <inertial pos="0.00842975 -0.045102 -0.0884733" quat="0.870583 0.455553 0.0434607 -0.180742" mass="0.0031019" diaginertia="7.25458e-06 5.10832e-06 2.59814e-06"/>
          <joint name="pinky_pip" pos="0 0 0" axis="0 1 0" range="0 1.57"/>
          <geom type="mesh" rgba="1 1 1 1" mesh="pinky_middle"/>
        </body>
      </body>
    </body>
    <body name="thumb_metacarpals_base1" pos="0.002384 -0.002009 0.071277" quat="0.999996 -0.00283225 0 0">
      <inertial pos="-0.00825004 0.0055 -0.0318467" quat="0.707107 0.707107 0 0" mass="0.000312218" diaginertia="1.10352e-08 1.0968e-08 1.03391e-09"/>
      <joint name="thumb_cmc_roll" pos="0 0 0" axis="-1 0 0" range="-0.6 0.6"/>
      <geom type="mesh" rgba="1 1 1 1" mesh="thumb_metacarpals_base1"/>
      <body name="thumb_metacarpals_base2" pos="0.02725 -0.008383 -0.0024" quat="1 0 0 5.7435e-05">
        <inertial pos="0.000318716 -0.00718338 0.00156864" quat="0.570424 0.399422 0.414998 0.585538" mass="0.000612302" diaginertia="2.54708e-08 1.44102e-08 1.19235e-08"/>
        <joint name="thumb_cmc_yaw" pos="0 0 0" axis="0 0 1" range="0 1.6"/>
        <geom type="mesh" rgba="1 1 1 1" mesh="thumb_metacarpals_base2"/>
        <body name="thumb_metacarpals" pos="0.0063626 -0.01451 0.0040125" quat="0.500353 0.499253 -0.514046 0.485953">
          <inertial pos="-0.0142748 0.0053204 0.00526553" mass="8.32841e-05" diaginertia="8.35186e-10 7.22775e-10 1.98746e-10"/>
          <joint name="thumb_cmc_pitch" pos="0 0 0" axis="0 1 0" range="0 1"/>
          <geom type="mesh" rgba="1 1 1 1" mesh="thumb_metacarpals"/>
          <body name="thumb_proximal" pos="-0.0039464 0 0.034242" quat="0.999909 0 0.0134861 0">
            <inertial pos="-0.018474 -0.0002 0.0462329" quat="0 0.728864 0 0.684658" mass="0.000276349" diaginertia="3.59254e-09 1.86536e-09 1.86536e-09"/>
            <joint name="thumb_mcp" pos="0 0 0" axis="0 1 0" range="0 1.57"/>
            <geom type="mesh" rgba="1 1 1 1" mesh="thumb_proximal"/>
            <body name="thumb_distal" pos="-0.0056449 0 0.045952" quat="0.998063 0 -0.0622048 0">
              <inertial pos="0.0178855 0.0197272 -0.0945726" quat="0.781247 0.0825532 0.239491 0.57051" mass="0.0031019" diaginertia="7.23521e-06 5.14386e-06 2.58196e-06"/>
              <joint name="thumb_ip" pos="0 0 0" axis="0 1 0" range="0 1.57"/>
              <geom type="mesh" rgba="1 1 1 1" mesh="thumb_distal"/>
            </body>
          </body>
        </body>
      </body>
    </body>
  </worldbody>
  <!--
  Joint 0: index_mcp_roll
Joint 1: index_mcp_pitch
Joint 2: index_pip
Joint 3: middle_mcp_roll
Joint 4: middle_mcp_pitch
Joint 5: middle_pip
Joint 6: ring_mcp_roll
Joint 7: ring_mcp_pitch
Joint 8: ring_pip
Joint 9: pinky_mcp_roll
Joint 10: pinky_mcp_pitch
Joint 11: pinky_pip
Joint 12: thumb_cmc_roll
Joint 13: thumb_cmc_yaw
Joint 14: thumb_cmc_pitch
Joint 15: thumb_mcp
Joint 16: thumb_ip
  -->
  <actuator>
      <position name="index_pos0" joint="index_mcp_roll" kp="10" ctrlrange="-0.26 0.26"/>
      <position name="index_pos1" joint="index_mcp_pitch" kp="10" ctrlrange="0 1.396"/>
      <position name="index_pos2" joint="index_pip" kp="10" ctrlrange="0 1.57"/>
      
      <position name="middle_pos0" joint="middle_mcp_roll" kp="10" ctrlrange="0 1.57"/>
      <position name="middle_pos1" joint="middle_mcp_pitch" kp="10" ctrlrange="0 1.57"/>
      <position name="middle_pos2" joint="middle_pip" kp="10" ctrlrange="0 1.57"/>

      
      <position name="ring_pos0" joint="ring_mcp_roll" kp="10" ctrlrange="-0.26 0.26"/>
      <position name="ring_pos1" joint="ring_mcp_pitch" kp="10" ctrlrange="0 1.57"/>
      <position name="ring_pos2" joint="ring_pip" kp="10" ctrlrange="0 1.57"/>>
      
      <position name="little_pos0" joint="pinky_mcp_roll" kp="10" ctrlrange="-0.26 0.26"/>
      <position name="little_pos1" joint="pinky_mcp_pitch" kp="10" ctrlrange="0 1.57"/>
      <position name="little_pos2" joint="pinky_pip" kp="10" ctrlrange="0 1.57"/>

      <position name="thumb_pos0" joint="thumb_cmc_roll" kp="10" ctrlrange="-0.1396 0.349"/>
      <position name="thumb_pos1" joint="thumb_cmc_yaw" kp="10" ctrlrange="0 1.57"/>
      <position name="thumb_pos2" joint="thumb_cmc_pitch" kp="10" ctrlrange="-1.57 0"/>
      <position name="thumb_pos3" joint="thumb_mcp" kp="10" ctrlrange="-1.57 0"/>
      <position name="thumb_pos4" joint="thumb_ip" kp="10" ctrlrange="-1.57 0"/>
  </actuator>
</mujoco>
