<mujoco model="linkerhand_o7_right">
    <compiler angle="radian" />
    <size njmax="500" nconmax="100" />
    <asset>
        <!-- 蓝白棋盘纹理 -->
        <texture name="grid_tex" type="2d" builtin="checker" rgb1="0.2 0.3 0.8" rgb2="1 1 1" width="512" height="512"/>
        
        <!-- 关联纹理的材质 -->
        <material name="grid_material" texture="grid_tex" texrepeat="10 10" specular="0.3" shininess="0.5"/>
        <mesh name="base_link" file="base_link.STL" />
        <mesh name="thumb_link0" file="thumb_link0.STL" />
        <mesh name="thumb_link1" file="thumb_link1.STL" />
        <mesh name="thumb_link2" file="thumb_link2.STL" />
        <mesh name="thumb_link3" file="thumb_link3.STL" />
        <mesh name="thumb_link4" file="thumb_link4.STL" />
        <mesh name="thumb_link5" file="thumb_link5.STL" />
        <mesh name="index_link0" file="index_link0.STL" />
        <mesh name="index_link1" file="index_link1.STL" />
        <mesh name="index_link2" file="index_link2.STL" />
        <mesh name="index_link3" file="index_link3.STL" />
        <mesh name="index_link4" file="index_link4.STL" />
        <mesh name="middle_link0" file="middle_link0.STL" />
        <mesh name="middle_link1" file="middle_link1.STL" />
        <mesh name="middle_link2" file="middle_link2.STL" />
        <mesh name="middle_link3" file="middle_link3.STL" />
        <mesh name="ring_link0" file="ring_link0.STL" />
        <mesh name="ring_link1" file="ring_link1.STL" />
        <mesh name="ring_link2" file="ring_link2.STL" />
        <mesh name="ring_link3" file="ring_link3.STL" />
        <mesh name="ring_link4" file="ring_link4.STL" />
        <mesh name="little_link0" file="little_link0.STL" />
        <mesh name="little_link1" file="little_link1.STL" />
        <mesh name="little_link2" file="little_link2.STL" />
        <mesh name="little_link3" file="little_link3.STL" />
        <mesh name="little_link4" file="little_link4.STL" />
    </asset>
    <visual>
        <quality shadowsize="4096"/>
        <map znear="0.05"/>
        <global offwidth="1280" offheight="720"/>
    </visual>

  <default>
    <joint limited="true" damping="0.1" armature="0.01"/>
    <motor ctrllimited="true"/>
    <geom condim="3" contype="1" conaffinity="1" solref="0.01 1" solimp="0.9 0.95 0.001" friction="1.0 0.005 0.0001"/>
    <equality solref="0.01 1"/>
  </default>
    <worldbody>
    <!-- 蓝白方格地面 -->
        <geom 
        name="floor" 
        type="plane" 
        pos="0 0 0" 
        size="5 5 0.1" 
        material="grid_material"
        conaffinity="1" 
        condim="3"
        />
        <light directional="true" diffuse=".4 .4 .4" specular=".1 .1 .1" pos="0 0 5" dir="0 0 -1"/>
        <geom type="mesh" rgba="1 1 1 1" mesh="base_link" />
        <geom pos="0.011645 0.02293 0.12973" type="mesh" rgba="1 0.6 0 1" mesh="index_link0" />
        <geom pos="0.011645 -0.01507 0.12973" type="mesh" rgba="1 0.6 0 1" mesh="ring_link0" />
        <geom pos="0.013645 -0.03407 0.12473" type="mesh" rgba="1 0.6 0 1" mesh="little_link0" />
        <body name="thumb_link0" pos="-0.017939 0.018426 0.057469">
            <inertial pos="0.0231878 -0.00228979 -0.00230333" quat="0.186304 0.682904 -0.613061 0.35084" mass="0.0115253" diaginertia="4.37121e-06 3.168e-06 1.87569e-06" />
            <joint name="thumb_joint0" pos="0 0 0" axis="1 0 0" limited="true" range="0 1.54" />
            <geom type="mesh" rgba="0.4 0.4 0.4 1" mesh="thumb_link0" />
            <body name="thumb_link1" pos="0.0303 -0.0097852 -0.0097852" quat="0.872224 -0.361289 -0.126164 -0.304595">
                <inertial pos="-5.30054e-05 0.000521078 0.0153022" quat="0.671886 0.740655 -0.00048468 -2.01133e-05" mass="0.0170451" diaginertia="3.40365e-06 2.61468e-06 1.93956e-06" />
                <joint name="thumb_joint1" pos="0 0 0" axis="0 0 1" limited="true" range="-1.43 0" />
                <geom type="mesh" rgba="0.4 0.4 0.4 1" mesh="thumb_link1" />
                <body name="thumb_link2" pos="0.0039399 0.028731 0.012357" quat="0.959788 0.280726 0 0">
                    <inertial pos="-0.00445707 0.020789 -0.0017564" quat="0.758907 0.651199 -0.000433103 0.000104848" mass="0.0151262" diaginertia="4.07088e-06 3.0171e-06 1.34222e-06" />
                    <joint name="thumb_joint2" pos="0 0 0" axis="1 0 0" limited="true" range="0 0.44" />
                    <geom type="mesh" rgba="1 1 1 1" mesh="thumb_link2" />
                    <body name="thumb_link3" pos="-0.01062 0.050514 0" quat="0.99537 -0.0961214 0 0">
                        <inertial pos="0.0066161 0.01503 0.00044042" quat="0.51966 0.479591 -0.479089 0.520019" mass="0.0054986" diaginertia="9.94194e-07 8.897e-07 3.98196e-07" />
                        <joint name="thumb_joint3" pos="0 0 0" axis="1 0 0" limited="true" range="0 0.75" />
                        <geom type="mesh" rgba="0.50196 1 0.50196 1" mesh="thumb_link3" />
                        <body name="thumb_link4" pos="0.00532 0.036667 0" quat="0.998255 -0.0590506 0 0">
                            <inertial pos="0.0012996 0.0146213 0.000964046" quat="0.588218 0.391594 -0.392011 0.589051" mass="0.00540097" diaginertia="4.47191e-07 3.63974e-07 1.90089e-07" />
                            <joint name="thumb_joint4" pos="0 0 0" axis="1 0 0" limited="true" range="0 0.7" />
                            <geom type="mesh" rgba="1 1 1 1" mesh="thumb_link4" />
                            <geom pos="0.0023001 0.037723 0" quat="-3.64259e-06 -4.73241e-07 0.128836 0.991666" type="mesh" rgba="1 1 1 1" mesh="thumb_link5" />
                        </body>
                    </body>
                </body>
            </body>
        </body>
        <body name="index_link1" pos="-0.00112 0.03143 0.147305">
            <inertial pos="-0.00432247 -0.00844417 0.0189706" quat="0.98757 -0.00134839 -0.1561 -0.0183156" mass="0.00319124" diaginertia="2.91666e-07 2.67777e-07 1.37647e-07" />
            <joint name="index_joint1" pos="0 0 0" axis="0 1 0" limited="true" range="0 1.41" />
            <geom type="mesh" rgba="0.792157 0.819608 0.921569 1" mesh="index_link1" />
            <body name="index_link2" pos="-0.0051959 -0.0031156 0.033276">
                <inertial pos="-0.00408694 -0.00578281 0.0108961" quat="0.974253 -0.0202765 -0.224482 0.00521904" mass="0.00326733" diaginertia="2.97602e-07 2.61391e-07 1.21583e-07" />
                <joint name="index_joint2" pos="0 0 0" axis="0 1 0" limited="true" range="0 1.62" />
                <geom type="mesh" rgba="1 1 1 1" mesh="index_link2" />
                <body name="index_link3" pos="-0.0094663 -5.4404e-05 0.024474">
                    <inertial pos="-0.00571071 -0.00522636 0.0156925" quat="0.935586 -0.00416504 -0.353015 -0.00641165" mass="0.00411717" diaginertia="3.07149e-07 2.56695e-07 1.04416e-07" />
                    <joint name="index_joint3" pos="0 0 0" axis="0 1 0" limited="true" range="0 0.96" />
                    <geom type="mesh" rgba="1 1 1 1" mesh="index_link3" />
                    <geom pos="-0.014222 -0.00417 0.034954" type="mesh" rgba="1 1 1 1" mesh="index_link4" />
                </body>
            </body>
        </body>
        <body name="middle_link0" pos="-0.0031059 0.01243 0.1523">
            <inertial pos="-0.0043225 -0.0084442 0.018971" quat="0.987571 -0.00134849 -0.156095 -0.0183158" mass="0.0031912" diaginertia="2.91668e-07 2.67779e-07 1.37643e-07" />
            <joint name="middle_joint0" pos="0 0 0" axis="0 1 0" limited="true" range="0 1.41" />
            <geom type="mesh" rgba="0.79216 0.81961 0.92157 1" mesh="middle_link0" />
            <body name="middle_link1" pos="-0.0051959 -0.0031156 0.033276">
                <inertial pos="-0.00408694 -0.00578281 0.0108961" quat="0.974253 -0.0202765 -0.224482 0.00521904" mass="0.00326733" diaginertia="2.97602e-07 2.61391e-07 1.21583e-07" />
                <joint name="middle_joint1" pos="0 0 0" axis="0 1 0" limited="true" range="0 1.62" />
                <geom type="mesh" rgba="1 1 1 1" mesh="middle_link1" />
                <body name="middle_link2" pos="-0.0094663 -5.4404e-05 0.024474">
                    <inertial pos="-0.00571071 -0.00522636 0.0156925" quat="0.935586 -0.00416504 -0.353015 -0.00641165" mass="0.00411717" diaginertia="3.07149e-07 2.56695e-07 1.04416e-07" />
                    <joint name="middle_joint2" pos="0 0 0" axis="0 1 0" limited="true" range="0 0.96" />
                    <geom type="mesh" rgba="1 1 1 1" mesh="middle_link2" />
                    <geom pos="-0.014222 -0.00417 0.034954" type="mesh" rgba="1 1 1 1" mesh="middle_link3" />
                </body>
            </body>
        </body>
        <body name="ring_link1" pos="-0.00112 -0.00657 0.147305">
            <inertial pos="-0.00432247 -0.00844417 0.0189706" quat="0.98757 -0.00134839 -0.1561 -0.0183156" mass="0.00319124" diaginertia="2.91666e-07 2.67777e-07 1.37647e-07" />
            <joint name="ring_joint1" pos="0 0 0" axis="0 1 0" limited="true" range="0 1.41" />
            <geom type="mesh" rgba="0.792157 0.819608 0.921569 1" mesh="ring_link1" />
            <body name="ring_link2" pos="-0.0051959 -0.0031156 0.033276">
                <inertial pos="-0.00408695 -0.00578281 0.0108961" quat="0.974253 -0.0202766 -0.224482 0.00521876" mass="0.00326733" diaginertia="2.97602e-07 2.61391e-07 1.21583e-07" />
                <joint name="ring_joint2" pos="0 0 0" axis="0 1 0" limited="true" range="0 1.62" />
                <geom type="mesh" rgba="0.490196 0.490196 0.490196 1" mesh="ring_link2" />
                <body name="ring_link3" pos="-0.0094663 -5.4399e-05 0.024474">
                    <inertial pos="-0.00571071 -0.00522636 0.0156925" quat="0.935586 -0.00416504 -0.353015 -0.00641165" mass="0.00411717" diaginertia="3.07149e-07 2.56695e-07 1.04416e-07" />
                    <joint name="ring_joint3" pos="0 0 0" axis="0 1 0" limited="true" range="0 0.96" />
                    <geom type="mesh" rgba="1 1 1 1" mesh="ring_link3" />
                    <geom pos="-0.014222 -0.00417 0.034954" type="mesh" rgba="1 1 1 1" mesh="ring_link4" />
                </body>
            </body>
        </body>
        <body name="little_link1" pos="0.00088 -0.02557 0.142305">
            <inertial pos="-0.00432248 -0.00844417 0.0189706" quat="0.98757 -0.00134844 -0.1561 -0.0183159" mass="0.00319124" diaginertia="2.91666e-07 2.67777e-07 1.37647e-07" />
            <joint name="little_joint1" pos="0 0 0" axis="0 1 0" limited="true" range="0 1.41" />
            <geom type="mesh" rgba="0.490196 0.490196 0.490196 1" mesh="little_link1" />
            <body name="little_link2" pos="-0.0051959 -0.0031156 0.033276">
                <inertial pos="-0.00408694 -0.00578281 0.0108961" quat="0.974253 -0.0202765 -0.224482 0.00521904" mass="0.00326733" diaginertia="2.97602e-07 2.61391e-07 1.21583e-07" />
                <joint name="little_joint2" pos="0 0 0" axis="0 1 0" limited="true" range="0 1.62" />
                <geom type="mesh" rgba="1 1 1 1" mesh="little_link2" />
                <body name="little_link3" pos="-0.0094663 -5.4404e-05 0.024474">
                    <inertial pos="-0.00571072 -0.00522636 0.0156925" quat="0.935586 -0.00416514 -0.353015 -0.00641192" mass="0.00411717" diaginertia="3.07149e-07 2.56695e-07 1.04416e-07" />
                    <joint name="little_joint3" pos="0 0 0" axis="0 1 0" limited="true" range="0 0.96" />
                    <geom type="mesh" rgba="1 1 1 1" mesh="little_link3" />
                    <geom pos="-0.014222 -0.00417 0.034954" type="mesh" rgba="1 1 1 1" mesh="little_link4" />
                </body>
            </body>
        </body>
    </worldbody>
    <actuator>
        <position name="thumb_pos0" joint="thumb_joint0" kp="10" ctrlrange="-0.52 1.01"/>
        <position name="thumb_pos1" joint="thumb_joint1" kp="10" ctrlrange="0 1.43"/>
        <position name="thumb_pos2" joint="thumb_joint2" kp="10" ctrlrange="0 0.44"/>
        <position name="thumb_pos3" joint="thumb_joint3" kp="10" ctrlrange="0 1.45"/>
        <position name="thumb_pos4" joint="thumb_joint4" kp="10" ctrlrange="0 1.57"/>
        
        <position name="index_pos1" joint="index_joint1" kp="10" ctrlrange="0 1.41"/>
        <position name="index_pos2" joint="index_joint2" kp="10" ctrlrange="0 1.62"/>
        <position name="index_pos3" joint="index_joint3" kp="10" ctrlrange="0 0.96"/>
        
        <position name="middle_pos0" joint="middle_joint0" kp="10" ctrlrange="0 1.41"/>
        <position name="middle_pos1" joint="middle_joint1" kp="10" ctrlrange="0 1.62"/>
        <position name="middle_pos2" joint="middle_joint2" kp="10" ctrlrange="0 0.96"/>


        <position name="ring_pos1" joint="ring_joint1" kp="10" ctrlrange="0 1.41"/>
        <position name="ring_pos2" joint="ring_joint2" kp="10" ctrlrange="0 1.62"/>
        <position name="ring_pos3" joint="ring_joint3" kp="10" ctrlrange="0 0.96"/>

        <position name="little_pos1" joint="little_joint1" kp="10" ctrlrange="0 1.41"/>
        <position name="little_pos2" joint="little_joint2" kp="10" ctrlrange="0 1.62"/>
        <position name="little_pos3" joint="little_joint3" kp="10" ctrlrange="0 0.96"/>
    </actuator>
</mujoco>
